ERROR 2025-09-02 08:45:06,820 log 13 138528957946752 Internal Server Error: /
Traceback (most recent call last):
  File "/usr/local/lib/python3.11/site-packages/django/core/handlers/exception.py", line 55, in inner
    response = get_response(request)
               ^^^^^^^^^^^^^^^^^^^^^
  File "/usr/local/lib/python3.11/site-packages/django/core/handlers/base.py", line 197, in _get_response
    response = wrapped_callback(request, *callback_args, **callback_kwargs)
               ^^^^^^^^^^^^^^^^^^^^^^^^^^^^^^^^^^^^^^^^^^^^^^^^^^^^^^^^^^^^
  File "/usr/local/lib/python3.11/site-packages/django/views/generic/base.py", line 105, in view
    return self.dispatch(request, *args, **kwargs)
           ^^^^^^^^^^^^^^^^^^^^^^^^^^^^^^^^^^^^^^^
  File "/usr/local/lib/python3.11/site-packages/django/utils/decorators.py", line 48, in _wrapper
    return bound_method(*args, **kwargs)
           ^^^^^^^^^^^^^^^^^^^^^^^^^^^^^
  File "/usr/local/lib/python3.11/site-packages/django/utils/decorators.py", line 48, in _wrapper
    return bound_method(*args, **kwargs)
           ^^^^^^^^^^^^^^^^^^^^^^^^^^^^^
  File "/usr/local/lib/python3.11/site-packages/django/views/decorators/debug.py", line 143, in sensitive_post_parameters_wrapper
    return view(request, *args, **kwargs)
           ^^^^^^^^^^^^^^^^^^^^^^^^^^^^^^
  File "/usr/local/lib/python3.11/site-packages/django/utils/decorators.py", line 48, in _wrapper
    return bound_method(*args, **kwargs)
           ^^^^^^^^^^^^^^^^^^^^^^^^^^^^^
  File "/usr/local/lib/python3.11/site-packages/django/utils/decorators.py", line 192, in _view_wrapper
    result = _process_exception(request, e)
             ^^^^^^^^^^^^^^^^^^^^^^^^^^^^^^
  File "/usr/local/lib/python3.11/site-packages/django/utils/decorators.py", line 190, in _view_wrapper
    response = view_func(request, *args, **kwargs)
               ^^^^^^^^^^^^^^^^^^^^^^^^^^^^^^^^^^^
  File "/usr/local/lib/python3.11/site-packages/django/utils/decorators.py", line 48, in _wrapper
    return bound_method(*args, **kwargs)
           ^^^^^^^^^^^^^^^^^^^^^^^^^^^^^
  File "/usr/local/lib/python3.11/site-packages/django/views/decorators/cache.py", line 80, in _view_wrapper
    response = view_func(request, *args, **kwargs)
               ^^^^^^^^^^^^^^^^^^^^^^^^^^^^^^^^^^^
  File "/usr/local/lib/python3.11/site-packages/django/contrib/auth/views.py", line 89, in dispatch
    return super().dispatch(request, *args, **kwargs)
           ^^^^^^^^^^^^^^^^^^^^^^^^^^^^^^^^^^^^^^^^^^
  File "/usr/local/lib/python3.11/site-packages/django/views/generic/base.py", line 144, in dispatch
    return handler(request, *args, **kwargs)
           ^^^^^^^^^^^^^^^^^^^^^^^^^^^^^^^^^
  File "/usr/local/lib/python3.11/site-packages/django/views/generic/edit.py", line 151, in post
    return self.form_valid(form)
           ^^^^^^^^^^^^^^^^^^^^^
  File "/usr/local/lib/python3.11/site-packages/django/contrib/auth/views.py", line 108, in form_valid
    auth_login(self.request, form.get_user())
  File "/usr/local/lib/python3.11/site-packages/django/contrib/auth/__init__.py", line 197, in login
    user_logged_in.send(sender=user.__class__, request=request, user=user)
  File "/usr/local/lib/python3.11/site-packages/django/dispatch/dispatcher.py", line 189, in send
    response = receiver(signal=self, sender=sender, **named)
               ^^^^^^^^^^^^^^^^^^^^^^^^^^^^^^^^^^^^^^^^^^^^^
  File "/app/dashboard/signals.py", line 14, in on_user_login
    target_week_range = WeekRange.objects.order_by('-starting_day')[3]
        ~~~~~~~~~~~~~~~~~~~~~~~~~~~~~~~~~~~~~~~~~~~^^^
  File "/usr/local/lib/python3.11/site-packages/django/db/models/query.py", line 436, in __getitem__
    return qs._result_cache[0]
           ~~~~~~~~~~~~~~~~^^^
IndexError: list index out of range
ERROR 2025-09-02 08:45:50,516 log 13 138528957946752 Internal Server Error: /
Traceback (most recent call last):
  File "/usr/local/lib/python3.11/site-packages/django/core/handlers/exception.py", line 55, in inner
    response = get_response(request)
               ^^^^^^^^^^^^^^^^^^^^^
  File "/usr/local/lib/python3.11/site-packages/django/core/handlers/base.py", line 197, in _get_response
    response = wrapped_callback(request, *callback_args, **callback_kwargs)
               ^^^^^^^^^^^^^^^^^^^^^^^^^^^^^^^^^^^^^^^^^^^^^^^^^^^^^^^^^^^^
  File "/usr/local/lib/python3.11/site-packages/django/views/generic/base.py", line 105, in view
    return self.dispatch(request, *args, **kwargs)
           ^^^^^^^^^^^^^^^^^^^^^^^^^^^^^^^^^^^^^^^
  File "/usr/local/lib/python3.11/site-packages/django/utils/decorators.py", line 48, in _wrapper
    return bound_method(*args, **kwargs)
           ^^^^^^^^^^^^^^^^^^^^^^^^^^^^^
  File "/usr/local/lib/python3.11/site-packages/django/utils/decorators.py", line 48, in _wrapper
    return bound_method(*args, **kwargs)
           ^^^^^^^^^^^^^^^^^^^^^^^^^^^^^
  File "/usr/local/lib/python3.11/site-packages/django/views/decorators/debug.py", line 143, in sensitive_post_parameters_wrapper
    return view(request, *args, **kwargs)
           ^^^^^^^^^^^^^^^^^^^^^^^^^^^^^^
  File "/usr/local/lib/python3.11/site-packages/django/utils/decorators.py", line 48, in _wrapper
    return bound_method(*args, **kwargs)
           ^^^^^^^^^^^^^^^^^^^^^^^^^^^^^
  File "/usr/local/lib/python3.11/site-packages/django/utils/decorators.py", line 192, in _view_wrapper
    result = _process_exception(request, e)
             ^^^^^^^^^^^^^^^^^^^^^^^^^^^^^^
  File "/usr/local/lib/python3.11/site-packages/django/utils/decorators.py", line 190, in _view_wrapper
    response = view_func(request, *args, **kwargs)
               ^^^^^^^^^^^^^^^^^^^^^^^^^^^^^^^^^^^
  File "/usr/local/lib/python3.11/site-packages/django/utils/decorators.py", line 48, in _wrapper
    return bound_method(*args, **kwargs)
           ^^^^^^^^^^^^^^^^^^^^^^^^^^^^^
  File "/usr/local/lib/python3.11/site-packages/django/views/decorators/cache.py", line 80, in _view_wrapper
    response = view_func(request, *args, **kwargs)
               ^^^^^^^^^^^^^^^^^^^^^^^^^^^^^^^^^^^
  File "/usr/local/lib/python3.11/site-packages/django/contrib/auth/views.py", line 89, in dispatch
    return super().dispatch(request, *args, **kwargs)
           ^^^^^^^^^^^^^^^^^^^^^^^^^^^^^^^^^^^^^^^^^^
  File "/usr/local/lib/python3.11/site-packages/django/views/generic/base.py", line 144, in dispatch
    return handler(request, *args, **kwargs)
           ^^^^^^^^^^^^^^^^^^^^^^^^^^^^^^^^^
  File "/usr/local/lib/python3.11/site-packages/django/views/generic/edit.py", line 151, in post
    return self.form_valid(form)
           ^^^^^^^^^^^^^^^^^^^^^
  File "/usr/local/lib/python3.11/site-packages/django/contrib/auth/views.py", line 108, in form_valid
    auth_login(self.request, form.get_user())
  File "/usr/local/lib/python3.11/site-packages/django/contrib/auth/__init__.py", line 197, in login
    user_logged_in.send(sender=user.__class__, request=request, user=user)
  File "/usr/local/lib/python3.11/site-packages/django/dispatch/dispatcher.py", line 189, in send
    response = receiver(signal=self, sender=sender, **named)
               ^^^^^^^^^^^^^^^^^^^^^^^^^^^^^^^^^^^^^^^^^^^^^
  File "/app/dashboard/signals.py", line 14, in on_user_login
    target_week_range = WeekRange.objects.order_by('-starting_day')[3]
        ~~~~~~~~~~~~~~~~~~~~~~~~~~~~~~~~~~~~~~~~~~~^^^
  File "/usr/local/lib/python3.11/site-packages/django/db/models/query.py", line 436, in __getitem__
    return qs._result_cache[0]
           ~~~~~~~~~~~~~~~~^^^
IndexError: list index out of range
ERROR 2025-09-02 08:45:50,701 log 13 138528957946752 Internal Server Error: /
Traceback (most recent call last):
  File "/usr/local/lib/python3.11/site-packages/django/core/handlers/exception.py", line 55, in inner
    response = get_response(request)
               ^^^^^^^^^^^^^^^^^^^^^
  File "/usr/local/lib/python3.11/site-packages/django/core/handlers/base.py", line 197, in _get_response
    response = wrapped_callback(request, *callback_args, **callback_kwargs)
               ^^^^^^^^^^^^^^^^^^^^^^^^^^^^^^^^^^^^^^^^^^^^^^^^^^^^^^^^^^^^
  File "/usr/local/lib/python3.11/site-packages/django/views/generic/base.py", line 105, in view
    return self.dispatch(request, *args, **kwargs)
           ^^^^^^^^^^^^^^^^^^^^^^^^^^^^^^^^^^^^^^^
  File "/usr/local/lib/python3.11/site-packages/django/utils/decorators.py", line 48, in _wrapper
    return bound_method(*args, **kwargs)
           ^^^^^^^^^^^^^^^^^^^^^^^^^^^^^
  File "/usr/local/lib/python3.11/site-packages/django/utils/decorators.py", line 48, in _wrapper
    return bound_method(*args, **kwargs)
           ^^^^^^^^^^^^^^^^^^^^^^^^^^^^^
  File "/usr/local/lib/python3.11/site-packages/django/views/decorators/debug.py", line 143, in sensitive_post_parameters_wrapper
    return view(request, *args, **kwargs)
           ^^^^^^^^^^^^^^^^^^^^^^^^^^^^^^
  File "/usr/local/lib/python3.11/site-packages/django/utils/decorators.py", line 48, in _wrapper
    return bound_method(*args, **kwargs)
           ^^^^^^^^^^^^^^^^^^^^^^^^^^^^^
  File "/usr/local/lib/python3.11/site-packages/django/utils/decorators.py", line 192, in _view_wrapper
    result = _process_exception(request, e)
             ^^^^^^^^^^^^^^^^^^^^^^^^^^^^^^
  File "/usr/local/lib/python3.11/site-packages/django/utils/decorators.py", line 190, in _view_wrapper
    response = view_func(request, *args, **kwargs)
               ^^^^^^^^^^^^^^^^^^^^^^^^^^^^^^^^^^^
  File "/usr/local/lib/python3.11/site-packages/django/utils/decorators.py", line 48, in _wrapper
    return bound_method(*args, **kwargs)
           ^^^^^^^^^^^^^^^^^^^^^^^^^^^^^
  File "/usr/local/lib/python3.11/site-packages/django/views/decorators/cache.py", line 80, in _view_wrapper
    response = view_func(request, *args, **kwargs)
               ^^^^^^^^^^^^^^^^^^^^^^^^^^^^^^^^^^^
  File "/usr/local/lib/python3.11/site-packages/django/contrib/auth/views.py", line 89, in dispatch
    return super().dispatch(request, *args, **kwargs)
           ^^^^^^^^^^^^^^^^^^^^^^^^^^^^^^^^^^^^^^^^^^
  File "/usr/local/lib/python3.11/site-packages/django/views/generic/base.py", line 144, in dispatch
    return handler(request, *args, **kwargs)
           ^^^^^^^^^^^^^^^^^^^^^^^^^^^^^^^^^
  File "/usr/local/lib/python3.11/site-packages/django/views/generic/edit.py", line 151, in post
    return self.form_valid(form)
           ^^^^^^^^^^^^^^^^^^^^^
  File "/usr/local/lib/python3.11/site-packages/django/contrib/auth/views.py", line 108, in form_valid
    auth_login(self.request, form.get_user())
  File "/usr/local/lib/python3.11/site-packages/django/contrib/auth/__init__.py", line 197, in login
    user_logged_in.send(sender=user.__class__, request=request, user=user)
  File "/usr/local/lib/python3.11/site-packages/django/dispatch/dispatcher.py", line 189, in send
    response = receiver(signal=self, sender=sender, **named)
               ^^^^^^^^^^^^^^^^^^^^^^^^^^^^^^^^^^^^^^^^^^^^^
  File "/app/dashboard/signals.py", line 14, in on_user_login
    target_week_range = WeekRange.objects.order_by('-starting_day')[3]
        ~~~~~~~~~~~~~~~~~~~~~~~~~~~~~~~~~~~~~~~~~~~^^^
  File "/usr/local/lib/python3.11/site-packages/django/db/models/query.py", line 436, in __getitem__
    return qs._result_cache[0]
           ~~~~~~~~~~~~~~~~^^^
IndexError: list index out of range
ERROR 2025-09-02 08:45:58,531 log 13 138528957946752 Internal Server Error: /admin/login/
Traceback (most recent call last):
  File "/usr/local/lib/python3.11/site-packages/django/core/handlers/exception.py", line 55, in inner
    response = get_response(request)
               ^^^^^^^^^^^^^^^^^^^^^
  File "/usr/local/lib/python3.11/site-packages/django/core/handlers/base.py", line 197, in _get_response
    response = wrapped_callback(request, *callback_args, **callback_kwargs)
               ^^^^^^^^^^^^^^^^^^^^^^^^^^^^^^^^^^^^^^^^^^^^^^^^^^^^^^^^^^^^
  File "/usr/local/lib/python3.11/site-packages/django/utils/decorators.py", line 48, in _wrapper
    return bound_method(*args, **kwargs)
           ^^^^^^^^^^^^^^^^^^^^^^^^^^^^^
  File "/usr/local/lib/python3.11/site-packages/django/views/decorators/cache.py", line 80, in _view_wrapper
    response = view_func(request, *args, **kwargs)
               ^^^^^^^^^^^^^^^^^^^^^^^^^^^^^^^^^^^
  File "/usr/local/lib/python3.11/site-packages/django/contrib/admin/sites.py", line 449, in login
    return LoginView.as_view(**defaults)(request)
           ^^^^^^^^^^^^^^^^^^^^^^^^^^^^^^^^^^^^^^
  File "/usr/local/lib/python3.11/site-packages/django/views/generic/base.py", line 105, in view
    return self.dispatch(request, *args, **kwargs)
           ^^^^^^^^^^^^^^^^^^^^^^^^^^^^^^^^^^^^^^^
  File "/usr/local/lib/python3.11/site-packages/django/utils/decorators.py", line 48, in _wrapper
    return bound_method(*args, **kwargs)
           ^^^^^^^^^^^^^^^^^^^^^^^^^^^^^
  File "/usr/local/lib/python3.11/site-packages/django/utils/decorators.py", line 48, in _wrapper
    return bound_method(*args, **kwargs)
           ^^^^^^^^^^^^^^^^^^^^^^^^^^^^^
  File "/usr/local/lib/python3.11/site-packages/django/views/decorators/debug.py", line 143, in sensitive_post_parameters_wrapper
    return view(request, *args, **kwargs)
           ^^^^^^^^^^^^^^^^^^^^^^^^^^^^^^
  File "/usr/local/lib/python3.11/site-packages/django/utils/decorators.py", line 48, in _wrapper
    return bound_method(*args, **kwargs)
           ^^^^^^^^^^^^^^^^^^^^^^^^^^^^^
  File "/usr/local/lib/python3.11/site-packages/django/utils/decorators.py", line 192, in _view_wrapper
    result = _process_exception(request, e)
             ^^^^^^^^^^^^^^^^^^^^^^^^^^^^^^
  File "/usr/local/lib/python3.11/site-packages/django/utils/decorators.py", line 190, in _view_wrapper
    response = view_func(request, *args, **kwargs)
               ^^^^^^^^^^^^^^^^^^^^^^^^^^^^^^^^^^^
  File "/usr/local/lib/python3.11/site-packages/django/utils/decorators.py", line 48, in _wrapper
    return bound_method(*args, **kwargs)
           ^^^^^^^^^^^^^^^^^^^^^^^^^^^^^
  File "/usr/local/lib/python3.11/site-packages/django/views/decorators/cache.py", line 80, in _view_wrapper
    response = view_func(request, *args, **kwargs)
               ^^^^^^^^^^^^^^^^^^^^^^^^^^^^^^^^^^^
  File "/usr/local/lib/python3.11/site-packages/django/contrib/auth/views.py", line 89, in dispatch
    return super().dispatch(request, *args, **kwargs)
           ^^^^^^^^^^^^^^^^^^^^^^^^^^^^^^^^^^^^^^^^^^
  File "/usr/local/lib/python3.11/site-packages/django/views/generic/base.py", line 144, in dispatch
    return handler(request, *args, **kwargs)
           ^^^^^^^^^^^^^^^^^^^^^^^^^^^^^^^^^
  File "/usr/local/lib/python3.11/site-packages/django/views/generic/edit.py", line 151, in post
    return self.form_valid(form)
           ^^^^^^^^^^^^^^^^^^^^^
  File "/usr/local/lib/python3.11/site-packages/django/contrib/auth/views.py", line 108, in form_valid
    auth_login(self.request, form.get_user())
  File "/usr/local/lib/python3.11/site-packages/django/contrib/auth/__init__.py", line 197, in login
    user_logged_in.send(sender=user.__class__, request=request, user=user)
  File "/usr/local/lib/python3.11/site-packages/django/dispatch/dispatcher.py", line 189, in send
    response = receiver(signal=self, sender=sender, **named)
               ^^^^^^^^^^^^^^^^^^^^^^^^^^^^^^^^^^^^^^^^^^^^^
  File "/app/dashboard/signals.py", line 14, in on_user_login
    target_week_range = WeekRange.objects.order_by('-starting_day')[3]
        ~~~~~~~~~~~~~~~~~~~~~~~~~~~~~~~~~~~~~~~~~~~^^^
  File "/usr/local/lib/python3.11/site-packages/django/db/models/query.py", line 436, in __getitem__
    return qs._result_cache[0]
           ~~~~~~~~~~~~~~~~^^^
IndexError: list index out of range
ERROR 2025-09-02 09:15:43,261 log 14 129229678799744 Internal Server Error: /
Traceback (most recent call last):
  File "/usr/local/lib/python3.11/site-packages/django/core/handlers/exception.py", line 55, in inner
    response = get_response(request)
               ^^^^^^^^^^^^^^^^^^^^^
  File "/usr/local/lib/python3.11/site-packages/django/core/handlers/base.py", line 197, in _get_response
    response = wrapped_callback(request, *callback_args, **callback_kwargs)
               ^^^^^^^^^^^^^^^^^^^^^^^^^^^^^^^^^^^^^^^^^^^^^^^^^^^^^^^^^^^^
  File "/usr/local/lib/python3.11/site-packages/django/views/generic/base.py", line 105, in view
    return self.dispatch(request, *args, **kwargs)
           ^^^^^^^^^^^^^^^^^^^^^^^^^^^^^^^^^^^^^^^
  File "/usr/local/lib/python3.11/site-packages/django/utils/decorators.py", line 48, in _wrapper
    return bound_method(*args, **kwargs)
           ^^^^^^^^^^^^^^^^^^^^^^^^^^^^^
  File "/usr/local/lib/python3.11/site-packages/django/utils/decorators.py", line 48, in _wrapper
    return bound_method(*args, **kwargs)
           ^^^^^^^^^^^^^^^^^^^^^^^^^^^^^
  File "/usr/local/lib/python3.11/site-packages/django/views/decorators/debug.py", line 143, in sensitive_post_parameters_wrapper
    return view(request, *args, **kwargs)
           ^^^^^^^^^^^^^^^^^^^^^^^^^^^^^^
  File "/usr/local/lib/python3.11/site-packages/django/utils/decorators.py", line 48, in _wrapper
    return bound_method(*args, **kwargs)
           ^^^^^^^^^^^^^^^^^^^^^^^^^^^^^
  File "/usr/local/lib/python3.11/site-packages/django/utils/decorators.py", line 192, in _view_wrapper
    result = _process_exception(request, e)
             ^^^^^^^^^^^^^^^^^^^^^^^^^^^^^^
  File "/usr/local/lib/python3.11/site-packages/django/utils/decorators.py", line 190, in _view_wrapper
    response = view_func(request, *args, **kwargs)
               ^^^^^^^^^^^^^^^^^^^^^^^^^^^^^^^^^^^
  File "/usr/local/lib/python3.11/site-packages/django/utils/decorators.py", line 48, in _wrapper
    return bound_method(*args, **kwargs)
           ^^^^^^^^^^^^^^^^^^^^^^^^^^^^^
  File "/usr/local/lib/python3.11/site-packages/django/views/decorators/cache.py", line 80, in _view_wrapper
    response = view_func(request, *args, **kwargs)
               ^^^^^^^^^^^^^^^^^^^^^^^^^^^^^^^^^^^
  File "/usr/local/lib/python3.11/site-packages/django/contrib/auth/views.py", line 89, in dispatch
    return super().dispatch(request, *args, **kwargs)
           ^^^^^^^^^^^^^^^^^^^^^^^^^^^^^^^^^^^^^^^^^^
  File "/usr/local/lib/python3.11/site-packages/django/views/generic/base.py", line 144, in dispatch
    return handler(request, *args, **kwargs)
           ^^^^^^^^^^^^^^^^^^^^^^^^^^^^^^^^^
  File "/usr/local/lib/python3.11/site-packages/django/views/generic/edit.py", line 151, in post
    return self.form_valid(form)
           ^^^^^^^^^^^^^^^^^^^^^
  File "/usr/local/lib/python3.11/site-packages/django/contrib/auth/views.py", line 108, in form_valid
    auth_login(self.request, form.get_user())
  File "/usr/local/lib/python3.11/site-packages/django/contrib/auth/__init__.py", line 197, in login
    user_logged_in.send(sender=user.__class__, request=request, user=user)
  File "/usr/local/lib/python3.11/site-packages/django/dispatch/dispatcher.py", line 189, in send
    response = receiver(signal=self, sender=sender, **named)
               ^^^^^^^^^^^^^^^^^^^^^^^^^^^^^^^^^^^^^^^^^^^^^
  File "/app/dashboard/signals.py", line 14, in on_user_login
    target_week_range = WeekRange.objects.order_by('-starting_day')[3]
        ~~~~~~~~~~~~~~~~~~~~~~~~~~~~~~~~~~~~~~~~~~~^^^
  File "/usr/local/lib/python3.11/site-packages/django/db/models/query.py", line 436, in __getitem__
    return qs._result_cache[0]
           ~~~~~~~~~~~~~~~~^^^
IndexError: list index out of range
ERROR 2025-09-02 09:23:51,461 log 13 137765463587712 Internal Server Error: /dashboard/team/
Traceback (most recent call last):
  File "/usr/local/lib/python3.11/site-packages/django/core/handlers/exception.py", line 55, in inner
    response = get_response(request)
               ^^^^^^^^^^^^^^^^^^^^^
  File "/usr/local/lib/python3.11/site-packages/django/core/handlers/base.py", line 197, in _get_response
    response = wrapped_callback(request, *callback_args, **callback_kwargs)
               ^^^^^^^^^^^^^^^^^^^^^^^^^^^^^^^^^^^^^^^^^^^^^^^^^^^^^^^^^^^^
  File "/usr/local/lib/python3.11/site-packages/django/views/generic/base.py", line 105, in view
    return self.dispatch(request, *args, **kwargs)
           ^^^^^^^^^^^^^^^^^^^^^^^^^^^^^^^^^^^^^^^
  File "/usr/local/lib/python3.11/site-packages/django/contrib/auth/mixins.py", line 73, in dispatch
    return super().dispatch(request, *args, **kwargs)
           ^^^^^^^^^^^^^^^^^^^^^^^^^^^^^^^^^^^^^^^^^^
  File "/usr/local/lib/python3.11/site-packages/django/views/generic/base.py", line 144, in dispatch
    return handler(request, *args, **kwargs)
           ^^^^^^^^^^^^^^^^^^^^^^^^^^^^^^^^^
  File "/app/dashboard/views.py", line 1120, in get
    team_name = team.name
                ^^^^^^^^^
AttributeError: 'NoneType' object has no attribute 'name'
ERROR 2025-09-02 09:23:54,856 log 13 137765463587712 Internal Server Error: /dashboard/team/
Traceback (most recent call last):
  File "/usr/local/lib/python3.11/site-packages/django/core/handlers/exception.py", line 55, in inner
    response = get_response(request)
               ^^^^^^^^^^^^^^^^^^^^^
  File "/usr/local/lib/python3.11/site-packages/django/core/handlers/base.py", line 197, in _get_response
    response = wrapped_callback(request, *callback_args, **callback_kwargs)
               ^^^^^^^^^^^^^^^^^^^^^^^^^^^^^^^^^^^^^^^^^^^^^^^^^^^^^^^^^^^^
  File "/usr/local/lib/python3.11/site-packages/django/views/generic/base.py", line 105, in view
    return self.dispatch(request, *args, **kwargs)
           ^^^^^^^^^^^^^^^^^^^^^^^^^^^^^^^^^^^^^^^
  File "/usr/local/lib/python3.11/site-packages/django/contrib/auth/mixins.py", line 73, in dispatch
    return super().dispatch(request, *args, **kwargs)
           ^^^^^^^^^^^^^^^^^^^^^^^^^^^^^^^^^^^^^^^^^^
  File "/usr/local/lib/python3.11/site-packages/django/views/generic/base.py", line 144, in dispatch
    return handler(request, *args, **kwargs)
           ^^^^^^^^^^^^^^^^^^^^^^^^^^^^^^^^^
  File "/app/dashboard/views.py", line 1120, in get
    team_name = team.name
                ^^^^^^^^^
AttributeError: 'NoneType' object has no attribute 'name'
ERROR 2025-09-02 09:28:07,376 log 13 137765463587712 Internal Server Error: /dashboard/team/
Traceback (most recent call last):
  File "/usr/local/lib/python3.11/site-packages/django/core/handlers/exception.py", line 55, in inner
    response = get_response(request)
               ^^^^^^^^^^^^^^^^^^^^^
  File "/usr/local/lib/python3.11/site-packages/django/core/handlers/base.py", line 197, in _get_response
    response = wrapped_callback(request, *callback_args, **callback_kwargs)
               ^^^^^^^^^^^^^^^^^^^^^^^^^^^^^^^^^^^^^^^^^^^^^^^^^^^^^^^^^^^^
  File "/usr/local/lib/python3.11/site-packages/django/views/generic/base.py", line 105, in view
    return self.dispatch(request, *args, **kwargs)
           ^^^^^^^^^^^^^^^^^^^^^^^^^^^^^^^^^^^^^^^
  File "/usr/local/lib/python3.11/site-packages/django/contrib/auth/mixins.py", line 73, in dispatch
    return super().dispatch(request, *args, **kwargs)
           ^^^^^^^^^^^^^^^^^^^^^^^^^^^^^^^^^^^^^^^^^^
  File "/usr/local/lib/python3.11/site-packages/django/views/generic/base.py", line 144, in dispatch
    return handler(request, *args, **kwargs)
           ^^^^^^^^^^^^^^^^^^^^^^^^^^^^^^^^^
  File "/app/dashboard/views.py", line 1120, in get
    team_name = team.name
                ^^^^^^^^^
AttributeError: 'NoneType' object has no attribute 'name'
ERROR 2025-09-02 09:29:47,610 log 13 137765463587712 Internal Server Error: /dashboard/account/1
Traceback (most recent call last):
  File "/usr/local/lib/python3.11/site-packages/django/db/backends/utils.py", line 105, in _execute
    return self.cursor.execute(sql, params)
           ^^^^^^^^^^^^^^^^^^^^^^^^^^^^^^^^
psycopg2.errors.UniqueViolation: duplicate key value violates unique constraint "dashboard_document_pkey"
DETAIL:  Key (id)=(1) already exists.


The above exception was the direct cause of the following exception:

Traceback (most recent call last):
  File "/usr/local/lib/python3.11/site-packages/django/core/handlers/exception.py", line 55, in inner
    response = get_response(request)
               ^^^^^^^^^^^^^^^^^^^^^
  File "/usr/local/lib/python3.11/site-packages/django/core/handlers/base.py", line 197, in _get_response
    response = wrapped_callback(request, *callback_args, **callback_kwargs)
               ^^^^^^^^^^^^^^^^^^^^^^^^^^^^^^^^^^^^^^^^^^^^^^^^^^^^^^^^^^^^
  File "/usr/local/lib/python3.11/site-packages/django/views/generic/base.py", line 105, in view
    return self.dispatch(request, *args, **kwargs)
           ^^^^^^^^^^^^^^^^^^^^^^^^^^^^^^^^^^^^^^^
  File "/usr/local/lib/python3.11/site-packages/django/contrib/auth/mixins.py", line 73, in dispatch
    return super().dispatch(request, *args, **kwargs)
           ^^^^^^^^^^^^^^^^^^^^^^^^^^^^^^^^^^^^^^^^^^
  File "/usr/local/lib/python3.11/site-packages/django/views/generic/base.py", line 144, in dispatch
    return handler(request, *args, **kwargs)
           ^^^^^^^^^^^^^^^^^^^^^^^^^^^^^^^^^
  File "/app/dashboard/views.py", line 66, in get
    generate_report(team)
  File "/app/dashboard/scheduler.py", line 130, in generate_report
    Document.objects.create(file = path, owner=team.team_lead,
  File "/usr/local/lib/python3.11/site-packages/django/db/models/manager.py", line 87, in manager_method
    return getattr(self.get_queryset(), name)(*args, **kwargs)
           ^^^^^^^^^^^^^^^^^^^^^^^^^^^^^^^^^^^^^^^^^^^^^^^^^^^
  File "/usr/local/lib/python3.11/site-packages/django/db/models/query.py", line 663, in create
    obj.save(force_insert=True, using=self.db)
  File "/usr/local/lib/python3.11/site-packages/django/db/models/base.py", line 902, in save
    self.save_base(
  File "/usr/local/lib/python3.11/site-packages/django/db/models/base.py", line 1008, in save_base
    updated = self._save_table(
              ^^^^^^^^^^^^^^^^^
  File "/usr/local/lib/python3.11/site-packages/django/db/models/base.py", line 1169, in _save_table
    results = self._do_insert(
              ^^^^^^^^^^^^^^^^
  File "/usr/local/lib/python3.11/site-packages/django/db/models/base.py", line 1210, in _do_insert
    return manager._insert(
           ^^^^^^^^^^^^^^^^
  File "/usr/local/lib/python3.11/site-packages/django/db/models/manager.py", line 87, in manager_method
    return getattr(self.get_queryset(), name)(*args, **kwargs)
           ^^^^^^^^^^^^^^^^^^^^^^^^^^^^^^^^^^^^^^^^^^^^^^^^^^^
  File "/usr/local/lib/python3.11/site-packages/django/db/models/query.py", line 1868, in _insert
    return query.get_compiler(using=using).execute_sql(returning_fields)
           ^^^^^^^^^^^^^^^^^^^^^^^^^^^^^^^^^^^^^^^^^^^^^^^^^^^^^^^^^^^^^
  File "/usr/local/lib/python3.11/site-packages/django/db/models/sql/compiler.py", line 1882, in execute_sql
    cursor.execute(sql, params)
  File "/usr/local/lib/python3.11/site-packages/django/db/backends/utils.py", line 79, in execute
    return self._execute_with_wrappers(
           ^^^^^^^^^^^^^^^^^^^^^^^^^^^^
  File "/usr/local/lib/python3.11/site-packages/django/db/backends/utils.py", line 92, in _execute_with_wrappers
    return executor(sql, params, many, context)
           ^^^^^^^^^^^^^^^^^^^^^^^^^^^^^^^^^^^^
  File "/usr/local/lib/python3.11/site-packages/django/db/backends/utils.py", line 100, in _execute
    with self.db.wrap_database_errors:
  File "/usr/local/lib/python3.11/site-packages/django/db/utils.py", line 91, in __exit__
    raise dj_exc_value.with_traceback(traceback) from exc_value
  File "/usr/local/lib/python3.11/site-packages/django/db/backends/utils.py", line 105, in _execute
    return self.cursor.execute(sql, params)
           ^^^^^^^^^^^^^^^^^^^^^^^^^^^^^^^^
django.db.utils.IntegrityError: duplicate key value violates unique constraint "dashboard_document_pkey"
DETAIL:  Key (id)=(1) already exists.

ERROR 2025-09-02 09:35:57,634 log 13 129192202791808 Internal Server Error: /dashboard/team/
Traceback (most recent call last):
  File "/usr/local/lib/python3.11/site-packages/django/core/handlers/exception.py", line 55, in inner
    response = get_response(request)
               ^^^^^^^^^^^^^^^^^^^^^
  File "/usr/local/lib/python3.11/site-packages/django/core/handlers/base.py", line 197, in _get_response
    response = wrapped_callback(request, *callback_args, **callback_kwargs)
               ^^^^^^^^^^^^^^^^^^^^^^^^^^^^^^^^^^^^^^^^^^^^^^^^^^^^^^^^^^^^
  File "/usr/local/lib/python3.11/site-packages/django/views/generic/base.py", line 105, in view
    return self.dispatch(request, *args, **kwargs)
           ^^^^^^^^^^^^^^^^^^^^^^^^^^^^^^^^^^^^^^^
  File "/usr/local/lib/python3.11/site-packages/django/contrib/auth/mixins.py", line 73, in dispatch
    return super().dispatch(request, *args, **kwargs)
           ^^^^^^^^^^^^^^^^^^^^^^^^^^^^^^^^^^^^^^^^^^
  File "/usr/local/lib/python3.11/site-packages/django/views/generic/base.py", line 144, in dispatch
    return handler(request, *args, **kwargs)
           ^^^^^^^^^^^^^^^^^^^^^^^^^^^^^^^^^
  File "/app/dashboard/views.py", line 1120, in get
    team_name = team.name
                ^^^^^^^^^
AttributeError: 'NoneType' object has no attribute 'name'
ERROR 2025-09-02 09:36:00,988 log 13 129192202791808 Internal Server Error: /dashboard/account/1
Traceback (most recent call last):
  File "/usr/local/lib/python3.11/site-packages/django/core/handlers/exception.py", line 55, in inner
    response = get_response(request)
               ^^^^^^^^^^^^^^^^^^^^^
  File "/usr/local/lib/python3.11/site-packages/django/core/handlers/base.py", line 197, in _get_response
    response = wrapped_callback(request, *callback_args, **callback_kwargs)
               ^^^^^^^^^^^^^^^^^^^^^^^^^^^^^^^^^^^^^^^^^^^^^^^^^^^^^^^^^^^^
  File "/usr/local/lib/python3.11/site-packages/django/views/generic/base.py", line 105, in view
    return self.dispatch(request, *args, **kwargs)
           ^^^^^^^^^^^^^^^^^^^^^^^^^^^^^^^^^^^^^^^
  File "/usr/local/lib/python3.11/site-packages/django/contrib/auth/mixins.py", line 73, in dispatch
    return super().dispatch(request, *args, **kwargs)
           ^^^^^^^^^^^^^^^^^^^^^^^^^^^^^^^^^^^^^^^^^^
  File "/usr/local/lib/python3.11/site-packages/django/views/generic/base.py", line 144, in dispatch
    return handler(request, *args, **kwargs)
           ^^^^^^^^^^^^^^^^^^^^^^^^^^^^^^^^^
  File "/app/dashboard/views.py", line 66, in get
    generate_report(team)
  File "/app/dashboard/scheduler.py", line 89, in generate_report
    story.append(Paragraph(f"Team {team.name}'s report ({now.strftime('%Y-%m-%d')})", header_style))
                                   ^^^^^^^^^
AttributeError: 'NoneType' object has no attribute 'name'
ERROR 2025-09-02 09:46:07,775 log 13 132804540717952 Internal Server Error: /dashboard/team/
Traceback (most recent call last):
  File "/usr/local/lib/python3.11/site-packages/django/core/handlers/exception.py", line 55, in inner
    response = get_response(request)
               ^^^^^^^^^^^^^^^^^^^^^
  File "/usr/local/lib/python3.11/site-packages/django/core/handlers/base.py", line 197, in _get_response
    response = wrapped_callback(request, *callback_args, **callback_kwargs)
               ^^^^^^^^^^^^^^^^^^^^^^^^^^^^^^^^^^^^^^^^^^^^^^^^^^^^^^^^^^^^
  File "/usr/local/lib/python3.11/site-packages/django/views/generic/base.py", line 105, in view
    return self.dispatch(request, *args, **kwargs)
           ^^^^^^^^^^^^^^^^^^^^^^^^^^^^^^^^^^^^^^^
  File "/usr/local/lib/python3.11/site-packages/django/contrib/auth/mixins.py", line 73, in dispatch
    return super().dispatch(request, *args, **kwargs)
           ^^^^^^^^^^^^^^^^^^^^^^^^^^^^^^^^^^^^^^^^^^
  File "/usr/local/lib/python3.11/site-packages/django/views/generic/base.py", line 144, in dispatch
    return handler(request, *args, **kwargs)
           ^^^^^^^^^^^^^^^^^^^^^^^^^^^^^^^^^
  File "/app/dashboard/views.py", line 1115, in get
    reports_list.append(Document.objects.get(object_id=rep.id))
                        ^^^^^^^^^^^^^^^^^^^^^^^^^^^^^^^^^^^^^^
  File "/usr/local/lib/python3.11/site-packages/django/db/models/manager.py", line 87, in manager_method
    return getattr(self.get_queryset(), name)(*args, **kwargs)
           ^^^^^^^^^^^^^^^^^^^^^^^^^^^^^^^^^^^^^^^^^^^^^^^^^^^
  File "/usr/local/lib/python3.11/site-packages/django/db/models/query.py", line 636, in get
    raise self.model.MultipleObjectsReturned(
dashboard.models.Document.MultipleObjectsReturned: get() returned more than one Document -- it returned 2!
ERROR 2025-09-02 09:46:09,868 log 13 132804540717952 Internal Server Error: /dashboard/team/
Traceback (most recent call last):
  File "/usr/local/lib/python3.11/site-packages/django/core/handlers/exception.py", line 55, in inner
    response = get_response(request)
               ^^^^^^^^^^^^^^^^^^^^^
  File "/usr/local/lib/python3.11/site-packages/django/core/handlers/base.py", line 197, in _get_response
    response = wrapped_callback(request, *callback_args, **callback_kwargs)
               ^^^^^^^^^^^^^^^^^^^^^^^^^^^^^^^^^^^^^^^^^^^^^^^^^^^^^^^^^^^^
  File "/usr/local/lib/python3.11/site-packages/django/views/generic/base.py", line 105, in view
    return self.dispatch(request, *args, **kwargs)
           ^^^^^^^^^^^^^^^^^^^^^^^^^^^^^^^^^^^^^^^
  File "/usr/local/lib/python3.11/site-packages/django/contrib/auth/mixins.py", line 73, in dispatch
    return super().dispatch(request, *args, **kwargs)
           ^^^^^^^^^^^^^^^^^^^^^^^^^^^^^^^^^^^^^^^^^^
  File "/usr/local/lib/python3.11/site-packages/django/views/generic/base.py", line 144, in dispatch
    return handler(request, *args, **kwargs)
           ^^^^^^^^^^^^^^^^^^^^^^^^^^^^^^^^^
  File "/app/dashboard/views.py", line 1115, in get
    reports_list.append(Document.objects.get(object_id=rep.id))
                        ^^^^^^^^^^^^^^^^^^^^^^^^^^^^^^^^^^^^^^
  File "/usr/local/lib/python3.11/site-packages/django/db/models/manager.py", line 87, in manager_method
    return getattr(self.get_queryset(), name)(*args, **kwargs)
           ^^^^^^^^^^^^^^^^^^^^^^^^^^^^^^^^^^^^^^^^^^^^^^^^^^^
  File "/usr/local/lib/python3.11/site-packages/django/db/models/query.py", line 636, in get
    raise self.model.MultipleObjectsReturned(
dashboard.models.Document.MultipleObjectsReturned: get() returned more than one Document -- it returned 2!
ERROR 2025-09-02 09:46:12,003 log 13 132804540717952 Internal Server Error: /dashboard/team/
Traceback (most recent call last):
  File "/usr/local/lib/python3.11/site-packages/django/core/handlers/exception.py", line 55, in inner
    response = get_response(request)
               ^^^^^^^^^^^^^^^^^^^^^
  File "/usr/local/lib/python3.11/site-packages/django/core/handlers/base.py", line 197, in _get_response
    response = wrapped_callback(request, *callback_args, **callback_kwargs)
               ^^^^^^^^^^^^^^^^^^^^^^^^^^^^^^^^^^^^^^^^^^^^^^^^^^^^^^^^^^^^
  File "/usr/local/lib/python3.11/site-packages/django/views/generic/base.py", line 105, in view
    return self.dispatch(request, *args, **kwargs)
           ^^^^^^^^^^^^^^^^^^^^^^^^^^^^^^^^^^^^^^^
  File "/usr/local/lib/python3.11/site-packages/django/contrib/auth/mixins.py", line 73, in dispatch
    return super().dispatch(request, *args, **kwargs)
           ^^^^^^^^^^^^^^^^^^^^^^^^^^^^^^^^^^^^^^^^^^
  File "/usr/local/lib/python3.11/site-packages/django/views/generic/base.py", line 144, in dispatch
    return handler(request, *args, **kwargs)
           ^^^^^^^^^^^^^^^^^^^^^^^^^^^^^^^^^
  File "/app/dashboard/views.py", line 1115, in get
    reports_list.append(Document.objects.get(object_id=rep.id))
                        ^^^^^^^^^^^^^^^^^^^^^^^^^^^^^^^^^^^^^^
  File "/usr/local/lib/python3.11/site-packages/django/db/models/manager.py", line 87, in manager_method
    return getattr(self.get_queryset(), name)(*args, **kwargs)
           ^^^^^^^^^^^^^^^^^^^^^^^^^^^^^^^^^^^^^^^^^^^^^^^^^^^
  File "/usr/local/lib/python3.11/site-packages/django/db/models/query.py", line 636, in get
    raise self.model.MultipleObjectsReturned(
dashboard.models.Document.MultipleObjectsReturned: get() returned more than one Document -- it returned 2!
ERROR 2025-09-02 09:46:17,692 log 13 132804540717952 Internal Server Error: /dashboard/team/
Traceback (most recent call last):
  File "/usr/local/lib/python3.11/site-packages/django/core/handlers/exception.py", line 55, in inner
    response = get_response(request)
               ^^^^^^^^^^^^^^^^^^^^^
  File "/usr/local/lib/python3.11/site-packages/django/core/handlers/base.py", line 197, in _get_response
    response = wrapped_callback(request, *callback_args, **callback_kwargs)
               ^^^^^^^^^^^^^^^^^^^^^^^^^^^^^^^^^^^^^^^^^^^^^^^^^^^^^^^^^^^^
  File "/usr/local/lib/python3.11/site-packages/django/views/generic/base.py", line 105, in view
    return self.dispatch(request, *args, **kwargs)
           ^^^^^^^^^^^^^^^^^^^^^^^^^^^^^^^^^^^^^^^
  File "/usr/local/lib/python3.11/site-packages/django/contrib/auth/mixins.py", line 73, in dispatch
    return super().dispatch(request, *args, **kwargs)
           ^^^^^^^^^^^^^^^^^^^^^^^^^^^^^^^^^^^^^^^^^^
  File "/usr/local/lib/python3.11/site-packages/django/views/generic/base.py", line 144, in dispatch
    return handler(request, *args, **kwargs)
           ^^^^^^^^^^^^^^^^^^^^^^^^^^^^^^^^^
  File "/app/dashboard/views.py", line 1115, in get
    reports_list.append(Document.objects.get(object_id=rep.id))
                        ^^^^^^^^^^^^^^^^^^^^^^^^^^^^^^^^^^^^^^
  File "/usr/local/lib/python3.11/site-packages/django/db/models/manager.py", line 87, in manager_method
    return getattr(self.get_queryset(), name)(*args, **kwargs)
           ^^^^^^^^^^^^^^^^^^^^^^^^^^^^^^^^^^^^^^^^^^^^^^^^^^^
  File "/usr/local/lib/python3.11/site-packages/django/db/models/query.py", line 636, in get
    raise self.model.MultipleObjectsReturned(
dashboard.models.Document.MultipleObjectsReturned: get() returned more than one Document -- it returned 2!
ERROR 2025-09-02 09:53:37,197 log 13 132100324002688 Internal Server Error: /dashboard/account/1
Traceback (most recent call last):
  File "/usr/local/lib/python3.11/site-packages/django/core/handlers/exception.py", line 55, in inner
    response = get_response(request)
               ^^^^^^^^^^^^^^^^^^^^^
  File "/usr/local/lib/python3.11/site-packages/django/core/handlers/base.py", line 197, in _get_response
    response = wrapped_callback(request, *callback_args, **callback_kwargs)
               ^^^^^^^^^^^^^^^^^^^^^^^^^^^^^^^^^^^^^^^^^^^^^^^^^^^^^^^^^^^^
  File "/usr/local/lib/python3.11/site-packages/django/views/generic/base.py", line 105, in view
    return self.dispatch(request, *args, **kwargs)
           ^^^^^^^^^^^^^^^^^^^^^^^^^^^^^^^^^^^^^^^
  File "/usr/local/lib/python3.11/site-packages/django/contrib/auth/mixins.py", line 73, in dispatch
    return super().dispatch(request, *args, **kwargs)
           ^^^^^^^^^^^^^^^^^^^^^^^^^^^^^^^^^^^^^^^^^^
  File "/usr/local/lib/python3.11/site-packages/django/views/generic/base.py", line 144, in dispatch
    return handler(request, *args, **kwargs)
           ^^^^^^^^^^^^^^^^^^^^^^^^^^^^^^^^^
  File "/app/dashboard/views.py", line 113, in post
    save_profile_picture(self, file, employee)
  File "/app/dashboard/utility.py", line 81, in save_profile_picture
    file = Document.objects.get(file__icontains=file_name, object_id = user.id)
           ^^^^^^^^^^^^^^^^^^^^^^^^^^^^^^^^^^^^^^^^^^^^^^^^^^^^^^^^^^^^^^^^^^^^
  File "/usr/local/lib/python3.11/site-packages/django/db/models/manager.py", line 87, in manager_method
    return getattr(self.get_queryset(), name)(*args, **kwargs)
           ^^^^^^^^^^^^^^^^^^^^^^^^^^^^^^^^^^^^^^^^^^^^^^^^^^^
  File "/usr/local/lib/python3.11/site-packages/django/db/models/query.py", line 633, in get
    raise self.model.DoesNotExist(
dashboard.models.Document.DoesNotExist: Document matching query does not exist.
ERROR 2025-09-02 10:01:02,111 log 13 138601477008256 Internal Server Error: /dashboard/account/1
Traceback (most recent call last):
  File "/usr/local/lib/python3.11/site-packages/django/core/handlers/exception.py", line 55, in inner
    response = get_response(request)
               ^^^^^^^^^^^^^^^^^^^^^
  File "/usr/local/lib/python3.11/site-packages/django/core/handlers/base.py", line 197, in _get_response
    response = wrapped_callback(request, *callback_args, **callback_kwargs)
               ^^^^^^^^^^^^^^^^^^^^^^^^^^^^^^^^^^^^^^^^^^^^^^^^^^^^^^^^^^^^
  File "/usr/local/lib/python3.11/site-packages/django/views/generic/base.py", line 105, in view
    return self.dispatch(request, *args, **kwargs)
           ^^^^^^^^^^^^^^^^^^^^^^^^^^^^^^^^^^^^^^^
  File "/usr/local/lib/python3.11/site-packages/django/contrib/auth/mixins.py", line 73, in dispatch
    return super().dispatch(request, *args, **kwargs)
           ^^^^^^^^^^^^^^^^^^^^^^^^^^^^^^^^^^^^^^^^^^
  File "/usr/local/lib/python3.11/site-packages/django/views/generic/base.py", line 144, in dispatch
    return handler(request, *args, **kwargs)
           ^^^^^^^^^^^^^^^^^^^^^^^^^^^^^^^^^
  File "/app/dashboard/views.py", line 113, in post
    save_profile_picture(self, file, employee)
  File "/app/dashboard/utility.py", line 81, in save_profile_picture
    file = Document.objects.get(file__icontains=file_name, object_id = user.id)
           ^^^^^^^^^^^^^^^^^^^^^^^^^^^^^^^^^^^^^^^^^^^^^^^^^^^^^^^^^^^^^^^^^^^^
  File "/usr/local/lib/python3.11/site-packages/django/db/models/manager.py", line 87, in manager_method
    return getattr(self.get_queryset(), name)(*args, **kwargs)
           ^^^^^^^^^^^^^^^^^^^^^^^^^^^^^^^^^^^^^^^^^^^^^^^^^^^
  File "/usr/local/lib/python3.11/site-packages/django/db/models/query.py", line 633, in get
    raise self.model.DoesNotExist(
dashboard.models.Document.DoesNotExist: Document matching query does not exist.
ERROR 2025-09-02 10:13:29,786 log 13 131907105610624 Internal Server Error: /dashboard/pic_picture/35
Traceback (most recent call last):
  File "/usr/local/lib/python3.11/site-packages/django/core/handlers/exception.py", line 55, in inner
    response = get_response(request)
               ^^^^^^^^^^^^^^^^^^^^^
  File "/usr/local/lib/python3.11/site-packages/django/core/handlers/base.py", line 197, in _get_response
    response = wrapped_callback(request, *callback_args, **callback_kwargs)
               ^^^^^^^^^^^^^^^^^^^^^^^^^^^^^^^^^^^^^^^^^^^^^^^^^^^^^^^^^^^^
  File "/app/dashboard/views.py", line 1515, in stream_file
    response = FileResponse(open(file_path, 'rb') , as_attachment=True, filename=file.file.name)
                            ^^^^^^^^^^^^^^^^^^^^^
FileNotFoundError: [Errno 2] No such file or directory: '/app/media/userprofile/1/round_shape.webp'
ERROR 2025-09-02 10:13:32,055 log 13 131907105610624 Internal Server Error: /dashboard/pic_picture/35
Traceback (most recent call last):
  File "/usr/local/lib/python3.11/site-packages/django/core/handlers/exception.py", line 55, in inner
    response = get_response(request)
               ^^^^^^^^^^^^^^^^^^^^^
  File "/usr/local/lib/python3.11/site-packages/django/core/handlers/base.py", line 197, in _get_response
    response = wrapped_callback(request, *callback_args, **callback_kwargs)
               ^^^^^^^^^^^^^^^^^^^^^^^^^^^^^^^^^^^^^^^^^^^^^^^^^^^^^^^^^^^^
  File "/app/dashboard/views.py", line 1515, in stream_file
    response = FileResponse(open(file_path, 'rb') , as_attachment=True, filename=file.file.name)
                            ^^^^^^^^^^^^^^^^^^^^^
FileNotFoundError: [Errno 2] No such file or directory: '/app/media/userprofile/1/round_shape.webp'
ERROR 2025-09-02 10:13:40,718 log 13 131907105610624 Internal Server Error: /dashboard/pic_picture/35
Traceback (most recent call last):
  File "/usr/local/lib/python3.11/site-packages/django/core/handlers/exception.py", line 55, in inner
    response = get_response(request)
               ^^^^^^^^^^^^^^^^^^^^^
  File "/usr/local/lib/python3.11/site-packages/django/core/handlers/base.py", line 197, in _get_response
    response = wrapped_callback(request, *callback_args, **callback_kwargs)
               ^^^^^^^^^^^^^^^^^^^^^^^^^^^^^^^^^^^^^^^^^^^^^^^^^^^^^^^^^^^^
  File "/app/dashboard/views.py", line 1515, in stream_file
    response = FileResponse(open(file_path, 'rb') , as_attachment=True, filename=file.file.name)
                            ^^^^^^^^^^^^^^^^^^^^^
FileNotFoundError: [Errno 2] No such file or directory: '/app/media/userprofile/1/round_shape.webp'
ERROR 2025-09-02 10:13:42,074 log 13 131907105610624 Internal Server Error: /dashboard/pic_picture/35
Traceback (most recent call last):
  File "/usr/local/lib/python3.11/site-packages/django/core/handlers/exception.py", line 55, in inner
    response = get_response(request)
               ^^^^^^^^^^^^^^^^^^^^^
  File "/usr/local/lib/python3.11/site-packages/django/core/handlers/base.py", line 197, in _get_response
    response = wrapped_callback(request, *callback_args, **callback_kwargs)
               ^^^^^^^^^^^^^^^^^^^^^^^^^^^^^^^^^^^^^^^^^^^^^^^^^^^^^^^^^^^^
  File "/app/dashboard/views.py", line 1515, in stream_file
    response = FileResponse(open(file_path, 'rb') , as_attachment=True, filename=file.file.name)
                            ^^^^^^^^^^^^^^^^^^^^^
FileNotFoundError: [Errno 2] No such file or directory: '/app/media/userprofile/1/round_shape.webp'
ERROR 2025-09-02 10:15:32,237 log 13 135358947093376 Internal Server Error: /dashboard/pic_picture/35
Traceback (most recent call last):
  File "/usr/local/lib/python3.11/site-packages/django/core/handlers/exception.py", line 55, in inner
    response = get_response(request)
               ^^^^^^^^^^^^^^^^^^^^^
  File "/usr/local/lib/python3.11/site-packages/django/core/handlers/base.py", line 197, in _get_response
    response = wrapped_callback(request, *callback_args, **callback_kwargs)
               ^^^^^^^^^^^^^^^^^^^^^^^^^^^^^^^^^^^^^^^^^^^^^^^^^^^^^^^^^^^^
  File "/app/dashboard/views.py", line 1515, in stream_file
    response = FileResponse(open(file_path, 'rb') , as_attachment=True, filename=file.file.name)
                            ^^^^^^^^^^^^^^^^^^^^^
FileNotFoundError: [Errno 2] No such file or directory: '/app/media/userprofile/1/round_shape.webp'
ERROR 2025-09-02 10:15:43,158 log 13 135358947093376 Internal Server Error: /dashboard/pic_picture/35
Traceback (most recent call last):
  File "/usr/local/lib/python3.11/site-packages/django/core/handlers/exception.py", line 55, in inner
    response = get_response(request)
               ^^^^^^^^^^^^^^^^^^^^^
  File "/usr/local/lib/python3.11/site-packages/django/core/handlers/base.py", line 197, in _get_response
    response = wrapped_callback(request, *callback_args, **callback_kwargs)
               ^^^^^^^^^^^^^^^^^^^^^^^^^^^^^^^^^^^^^^^^^^^^^^^^^^^^^^^^^^^^
  File "/app/dashboard/views.py", line 1515, in stream_file
    response = FileResponse(open(file_path, 'rb') , as_attachment=True, filename=file.file.name)
                            ^^^^^^^^^^^^^^^^^^^^^
FileNotFoundError: [Errno 2] No such file or directory: '/app/media/userprofile/1/round_shape.webp'
ERROR 2025-09-02 10:33:40,901 log 13 125067107462016 Internal Server Error: /dashboard/account/1
Traceback (most recent call last):
  File "/usr/local/lib/python3.11/site-packages/django/core/handlers/exception.py", line 55, in inner
    response = get_response(request)
               ^^^^^^^^^^^^^^^^^^^^^
  File "/usr/local/lib/python3.11/site-packages/django/core/handlers/base.py", line 197, in _get_response
    response = wrapped_callback(request, *callback_args, **callback_kwargs)
               ^^^^^^^^^^^^^^^^^^^^^^^^^^^^^^^^^^^^^^^^^^^^^^^^^^^^^^^^^^^^
  File "/usr/local/lib/python3.11/site-packages/django/views/generic/base.py", line 105, in view
    return self.dispatch(request, *args, **kwargs)
           ^^^^^^^^^^^^^^^^^^^^^^^^^^^^^^^^^^^^^^^
  File "/usr/local/lib/python3.11/site-packages/django/contrib/auth/mixins.py", line 73, in dispatch
    return super().dispatch(request, *args, **kwargs)
           ^^^^^^^^^^^^^^^^^^^^^^^^^^^^^^^^^^^^^^^^^^
  File "/usr/local/lib/python3.11/site-packages/django/views/generic/base.py", line 144, in dispatch
    return handler(request, *args, **kwargs)
           ^^^^^^^^^^^^^^^^^^^^^^^^^^^^^^^^^
  File "/app/dashboard/views.py", line 113, in post
    save_profile_picture(self, file, employee)
  File "/app/dashboard/utility.py", line 81, in save_profile_picture
    file = Document.objects.get(file__icontains=file_name, object_id = user.id)
           ^^^^^^^^^^^^^^^^^^^^^^^^^^^^^^^^^^^^^^^^^^^^^^^^^^^^^^^^^^^^^^^^^^^^
  File "/usr/local/lib/python3.11/site-packages/django/db/models/manager.py", line 87, in manager_method
    return getattr(self.get_queryset(), name)(*args, **kwargs)
           ^^^^^^^^^^^^^^^^^^^^^^^^^^^^^^^^^^^^^^^^^^^^^^^^^^^
  File "/usr/local/lib/python3.11/site-packages/django/db/models/query.py", line 633, in get
    raise self.model.DoesNotExist(
dashboard.models.Document.DoesNotExist: Document matching query does not exist.
ERROR 2025-09-02 13:17:09,696 log 13 131773402147712 Internal Server Error: /dashboard/account/1
Traceback (most recent call last):
  File "/usr/local/lib/python3.11/site-packages/django/core/handlers/exception.py", line 55, in inner
    response = get_response(request)
               ^^^^^^^^^^^^^^^^^^^^^
  File "/usr/local/lib/python3.11/site-packages/django/core/handlers/base.py", line 197, in _get_response
    response = wrapped_callback(request, *callback_args, **callback_kwargs)
               ^^^^^^^^^^^^^^^^^^^^^^^^^^^^^^^^^^^^^^^^^^^^^^^^^^^^^^^^^^^^
  File "/usr/local/lib/python3.11/site-packages/django/views/generic/base.py", line 105, in view
    return self.dispatch(request, *args, **kwargs)
           ^^^^^^^^^^^^^^^^^^^^^^^^^^^^^^^^^^^^^^^
  File "/usr/local/lib/python3.11/site-packages/django/contrib/auth/mixins.py", line 73, in dispatch
    return super().dispatch(request, *args, **kwargs)
           ^^^^^^^^^^^^^^^^^^^^^^^^^^^^^^^^^^^^^^^^^^
  File "/usr/local/lib/python3.11/site-packages/django/views/generic/base.py", line 144, in dispatch
    return handler(request, *args, **kwargs)
           ^^^^^^^^^^^^^^^^^^^^^^^^^^^^^^^^^
  File "/app/dashboard/views.py", line 66, in get
    generate_report(team)
  File "/app/dashboard/scheduler.py", line 89, in generate_report
    story.append(Paragraph(f"Team {team.name}'s report ({now.strftime('%Y-%m-%d')})", header_style))
                                   ^^^^^^^^^
AttributeError: 'NoneType' object has no attribute 'name'
