Internal Server Error: /admin/dashboard/users/add/
Traceback (most recent call last):
  File "/usr/local/lib/python3.11/site-packages/django/core/handlers/exception.py", line 55, in inner
    response = get_response(request)
               ^^^^^^^^^^^^^^^^^^^^^
  File "/usr/local/lib/python3.11/site-packages/django/core/handlers/base.py", line 197, in _get_response
    response = wrapped_callback(request, *callback_args, **callback_kwargs)
               ^^^^^^^^^^^^^^^^^^^^^^^^^^^^^^^^^^^^^^^^^^^^^^^^^^^^^^^^^^^^
  File "/usr/local/lib/python3.11/site-packages/django/contrib/admin/options.py", line 719, in wrapper
    return self.admin_site.admin_view(view)(*args, **kwargs)
           ^^^^^^^^^^^^^^^^^^^^^^^^^^^^^^^^^^^^^^^^^^^^^^^^^
  File "/usr/local/lib/python3.11/site-packages/django/utils/decorators.py", line 192, in _view_wrapper
    result = _process_exception(request, e)
             ^^^^^^^^^^^^^^^^^^^^^^^^^^^^^^
  File "/usr/local/lib/python3.11/site-packages/django/utils/decorators.py", line 190, in _view_wrapper
    response = view_func(request, *args, **kwargs)
               ^^^^^^^^^^^^^^^^^^^^^^^^^^^^^^^^^^^
  File "/usr/local/lib/python3.11/site-packages/django/views/decorators/cache.py", line 80, in _view_wrapper
    response = view_func(request, *args, **kwargs)
               ^^^^^^^^^^^^^^^^^^^^^^^^^^^^^^^^^^^
  File "/usr/local/lib/python3.11/site-packages/django/contrib/admin/sites.py", line 246, in inner
    return view(request, *args, **kwargs)
           ^^^^^^^^^^^^^^^^^^^^^^^^^^^^^^
  File "/usr/local/lib/python3.11/site-packages/django/utils/decorators.py", line 48, in _wrapper
    return bound_method(*args, **kwargs)
           ^^^^^^^^^^^^^^^^^^^^^^^^^^^^^
  File "/usr/local/lib/python3.11/site-packages/django/views/decorators/debug.py", line 143, in sensitive_post_parameters_wrapper
    return view(request, *args, **kwargs)
           ^^^^^^^^^^^^^^^^^^^^^^^^^^^^^^
  File "/usr/local/lib/python3.11/site-packages/django/utils/decorators.py", line 48, in _wrapper
    return bound_method(*args, **kwargs)
           ^^^^^^^^^^^^^^^^^^^^^^^^^^^^^
  File "/usr/local/lib/python3.11/site-packages/django/utils/decorators.py", line 192, in _view_wrapper
    result = _process_exception(request, e)
             ^^^^^^^^^^^^^^^^^^^^^^^^^^^^^^
  File "/usr/local/lib/python3.11/site-packages/django/utils/decorators.py", line 190, in _view_wrapper
    response = view_func(request, *args, **kwargs)
               ^^^^^^^^^^^^^^^^^^^^^^^^^^^^^^^^^^^
  File "/usr/local/lib/python3.11/site-packages/django/contrib/auth/admin.py", line 124, in add_view
    return self._add_view(request, form_url, extra_context)
           ^^^^^^^^^^^^^^^^^^^^^^^^^^^^^^^^^^^^^^^^^^^^^^^^
  File "/usr/local/lib/python3.11/site-packages/django/contrib/auth/admin.py", line 152, in _add_view
    return super().add_view(request, form_url, extra_context)
           ^^^^^^^^^^^^^^^^^^^^^^^^^^^^^^^^^^^^^^^^^^^^^^^^^^
  File "/usr/local/lib/python3.11/site-packages/django/contrib/admin/options.py", line 1984, in add_view
    return self.changeform_view(request, None, form_url, extra_context)
           ^^^^^^^^^^^^^^^^^^^^^^^^^^^^^^^^^^^^^^^^^^^^^^^^^^^^^^^^^^^^
  File "/usr/local/lib/python3.11/site-packages/django/utils/decorators.py", line 48, in _wrapper
    return bound_method(*args, **kwargs)
           ^^^^^^^^^^^^^^^^^^^^^^^^^^^^^
  File "/usr/local/lib/python3.11/site-packages/django/utils/decorators.py", line 192, in _view_wrapper
    result = _process_exception(request, e)
             ^^^^^^^^^^^^^^^^^^^^^^^^^^^^^^
  File "/usr/local/lib/python3.11/site-packages/django/utils/decorators.py", line 190, in _view_wrapper
    response = view_func(request, *args, **kwargs)
               ^^^^^^^^^^^^^^^^^^^^^^^^^^^^^^^^^^^
  File "/usr/local/lib/python3.11/site-packages/django/contrib/admin/options.py", line 1843, in changeform_view
    return self._changeform_view(request, object_id, form_url, extra_context)
           ^^^^^^^^^^^^^^^^^^^^^^^^^^^^^^^^^^^^^^^^^^^^^^^^^^^^^^^^^^^^^^^^^^
  File "/usr/local/lib/python3.11/site-packages/django/contrib/admin/options.py", line 1894, in _changeform_view
    self.save_model(request, new_object, form, not add)
  File "/usr/local/lib/python3.11/site-packages/django/contrib/admin/options.py", line 1314, in save_model
    obj.save()
  File "/usr/local/lib/python3.11/site-packages/django/contrib/auth/base_user.py", line 65, in save
    super().save(*args, **kwargs)
  File "/usr/local/lib/python3.11/site-packages/django/db/models/base.py", line 902, in save
    self.save_base(
  File "/usr/local/lib/python3.11/site-packages/django/db/models/base.py", line 1023, in save_base
    post_save.send(
  File "/usr/local/lib/python3.11/site-packages/django/dispatch/dispatcher.py", line 189, in send
    response = receiver(signal=self, sender=sender, **named)
               ^^^^^^^^^^^^^^^^^^^^^^^^^^^^^^^^^^^^^^^^^^^^^
  File "/app/dashboard/signals.py", line 24, in create_schedule
    has_schedule = Schedule.objects.filter(user=instance).exists()
                   ^^^^^^^^^^^^^^^^^^^^^^^^^^^^^^^^^^^^^^
  File "/usr/local/lib/python3.11/site-packages/django/db/models/manager.py", line 87, in manager_method
    return getattr(self.get_queryset(), name)(*args, **kwargs)
           ^^^^^^^^^^^^^^^^^^^^^^^^^^^^^^^^^^^^^^^^^^^^^^^^^^^
  File "/usr/local/lib/python3.11/site-packages/django/db/models/query.py", line 1493, in filter
    return self._filter_or_exclude(False, args, kwargs)
           ^^^^^^^^^^^^^^^^^^^^^^^^^^^^^^^^^^^^^^^^^^^^
  File "/usr/local/lib/python3.11/site-packages/django/db/models/query.py", line 1511, in _filter_or_exclude
    clone._filter_or_exclude_inplace(negate, args, kwargs)
  File "/usr/local/lib/python3.11/site-packages/django/db/models/query.py", line 1518, in _filter_or_exclude_inplace
    self._query.add_q(Q(*args, **kwargs))
  File "/usr/local/lib/python3.11/site-packages/django/db/models/sql/query.py", line 1646, in add_q
    clause, _ = self._add_q(q_object, can_reuse)
                ^^^^^^^^^^^^^^^^^^^^^^^^^^^^^^^^
  File "/usr/local/lib/python3.11/site-packages/django/db/models/sql/query.py", line 1678, in _add_q
    child_clause, needed_inner = self.build_filter(
                                 ^^^^^^^^^^^^^^^^^^
  File "/usr/local/lib/python3.11/site-packages/django/db/models/sql/query.py", line 1563, in build_filter
    self.check_related_objects(join_info.final_field, value, join_info.opts)
  File "/usr/local/lib/python3.11/site-packages/django/db/models/sql/query.py", line 1372, in check_related_objects
    self.check_query_object_type(value, opts, field)
  File "/usr/local/lib/python3.11/site-packages/django/db/models/sql/query.py", line 1349, in check_query_object_type
    raise ValueError(
ValueError: Cannot query "Natasha2": Must be "UserProfile" instance.
Internal Server Error: /admin/dashboard/users/add/
Traceback (most recent call last):
  File "/usr/local/lib/python3.11/site-packages/django/core/handlers/exception.py", line 55, in inner
    response = get_response(request)
               ^^^^^^^^^^^^^^^^^^^^^
  File "/usr/local/lib/python3.11/site-packages/django/core/handlers/base.py", line 197, in _get_response
    response = wrapped_callback(request, *callback_args, **callback_kwargs)
               ^^^^^^^^^^^^^^^^^^^^^^^^^^^^^^^^^^^^^^^^^^^^^^^^^^^^^^^^^^^^
  File "/usr/local/lib/python3.11/site-packages/django/contrib/admin/options.py", line 719, in wrapper
    return self.admin_site.admin_view(view)(*args, **kwargs)
           ^^^^^^^^^^^^^^^^^^^^^^^^^^^^^^^^^^^^^^^^^^^^^^^^^
  File "/usr/local/lib/python3.11/site-packages/django/utils/decorators.py", line 192, in _view_wrapper
    result = _process_exception(request, e)
             ^^^^^^^^^^^^^^^^^^^^^^^^^^^^^^
  File "/usr/local/lib/python3.11/site-packages/django/utils/decorators.py", line 190, in _view_wrapper
    response = view_func(request, *args, **kwargs)
               ^^^^^^^^^^^^^^^^^^^^^^^^^^^^^^^^^^^
  File "/usr/local/lib/python3.11/site-packages/django/views/decorators/cache.py", line 80, in _view_wrapper
    response = view_func(request, *args, **kwargs)
               ^^^^^^^^^^^^^^^^^^^^^^^^^^^^^^^^^^^
  File "/usr/local/lib/python3.11/site-packages/django/contrib/admin/sites.py", line 246, in inner
    return view(request, *args, **kwargs)
           ^^^^^^^^^^^^^^^^^^^^^^^^^^^^^^
  File "/usr/local/lib/python3.11/site-packages/django/utils/decorators.py", line 48, in _wrapper
    return bound_method(*args, **kwargs)
           ^^^^^^^^^^^^^^^^^^^^^^^^^^^^^
  File "/usr/local/lib/python3.11/site-packages/django/views/decorators/debug.py", line 143, in sensitive_post_parameters_wrapper
    return view(request, *args, **kwargs)
           ^^^^^^^^^^^^^^^^^^^^^^^^^^^^^^
  File "/usr/local/lib/python3.11/site-packages/django/utils/decorators.py", line 48, in _wrapper
    return bound_method(*args, **kwargs)
           ^^^^^^^^^^^^^^^^^^^^^^^^^^^^^
  File "/usr/local/lib/python3.11/site-packages/django/utils/decorators.py", line 192, in _view_wrapper
    result = _process_exception(request, e)
             ^^^^^^^^^^^^^^^^^^^^^^^^^^^^^^
  File "/usr/local/lib/python3.11/site-packages/django/utils/decorators.py", line 190, in _view_wrapper
    response = view_func(request, *args, **kwargs)
               ^^^^^^^^^^^^^^^^^^^^^^^^^^^^^^^^^^^
  File "/usr/local/lib/python3.11/site-packages/django/contrib/auth/admin.py", line 124, in add_view
    return self._add_view(request, form_url, extra_context)
           ^^^^^^^^^^^^^^^^^^^^^^^^^^^^^^^^^^^^^^^^^^^^^^^^
  File "/usr/local/lib/python3.11/site-packages/django/contrib/auth/admin.py", line 152, in _add_view
    return super().add_view(request, form_url, extra_context)
           ^^^^^^^^^^^^^^^^^^^^^^^^^^^^^^^^^^^^^^^^^^^^^^^^^^
  File "/usr/local/lib/python3.11/site-packages/django/contrib/admin/options.py", line 1984, in add_view
    return self.changeform_view(request, None, form_url, extra_context)
           ^^^^^^^^^^^^^^^^^^^^^^^^^^^^^^^^^^^^^^^^^^^^^^^^^^^^^^^^^^^^
  File "/usr/local/lib/python3.11/site-packages/django/utils/decorators.py", line 48, in _wrapper
    return bound_method(*args, **kwargs)
           ^^^^^^^^^^^^^^^^^^^^^^^^^^^^^
  File "/usr/local/lib/python3.11/site-packages/django/utils/decorators.py", line 192, in _view_wrapper
    result = _process_exception(request, e)
             ^^^^^^^^^^^^^^^^^^^^^^^^^^^^^^
  File "/usr/local/lib/python3.11/site-packages/django/utils/decorators.py", line 190, in _view_wrapper
    response = view_func(request, *args, **kwargs)
               ^^^^^^^^^^^^^^^^^^^^^^^^^^^^^^^^^^^
  File "/usr/local/lib/python3.11/site-packages/django/contrib/admin/options.py", line 1843, in changeform_view
    return self._changeform_view(request, object_id, form_url, extra_context)
           ^^^^^^^^^^^^^^^^^^^^^^^^^^^^^^^^^^^^^^^^^^^^^^^^^^^^^^^^^^^^^^^^^^
  File "/usr/local/lib/python3.11/site-packages/django/contrib/admin/options.py", line 1894, in _changeform_view
    self.save_model(request, new_object, form, not add)
  File "/usr/local/lib/python3.11/site-packages/django/contrib/admin/options.py", line 1314, in save_model
    obj.save()
  File "/usr/local/lib/python3.11/site-packages/django/contrib/auth/base_user.py", line 65, in save
    super().save(*args, **kwargs)
  File "/usr/local/lib/python3.11/site-packages/django/db/models/base.py", line 902, in save
    self.save_base(
  File "/usr/local/lib/python3.11/site-packages/django/db/models/base.py", line 1023, in save_base
    post_save.send(
  File "/usr/local/lib/python3.11/site-packages/django/dispatch/dispatcher.py", line 189, in send
    response = receiver(signal=self, sender=sender, **named)
               ^^^^^^^^^^^^^^^^^^^^^^^^^^^^^^^^^^^^^^^^^^^^^
  File "/app/dashboard/signals.py", line 24, in create_schedule
    has_schedule = Schedule.objects.filter(user=instance).exists()
                   ^^^^^^^^^^^^^^^^^^^^^^^^^^^^^^^^^^^^^^
  File "/usr/local/lib/python3.11/site-packages/django/db/models/manager.py", line 87, in manager_method
    return getattr(self.get_queryset(), name)(*args, **kwargs)
           ^^^^^^^^^^^^^^^^^^^^^^^^^^^^^^^^^^^^^^^^^^^^^^^^^^^
  File "/usr/local/lib/python3.11/site-packages/django/db/models/query.py", line 1493, in filter
    return self._filter_or_exclude(False, args, kwargs)
           ^^^^^^^^^^^^^^^^^^^^^^^^^^^^^^^^^^^^^^^^^^^^
  File "/usr/local/lib/python3.11/site-packages/django/db/models/query.py", line 1511, in _filter_or_exclude
    clone._filter_or_exclude_inplace(negate, args, kwargs)
  File "/usr/local/lib/python3.11/site-packages/django/db/models/query.py", line 1518, in _filter_or_exclude_inplace
    self._query.add_q(Q(*args, **kwargs))
  File "/usr/local/lib/python3.11/site-packages/django/db/models/sql/query.py", line 1646, in add_q
    clause, _ = self._add_q(q_object, can_reuse)
                ^^^^^^^^^^^^^^^^^^^^^^^^^^^^^^^^
  File "/usr/local/lib/python3.11/site-packages/django/db/models/sql/query.py", line 1678, in _add_q
    child_clause, needed_inner = self.build_filter(
                                 ^^^^^^^^^^^^^^^^^^
  File "/usr/local/lib/python3.11/site-packages/django/db/models/sql/query.py", line 1563, in build_filter
    self.check_related_objects(join_info.final_field, value, join_info.opts)
  File "/usr/local/lib/python3.11/site-packages/django/db/models/sql/query.py", line 1372, in check_related_objects
    self.check_query_object_type(value, opts, field)
  File "/usr/local/lib/python3.11/site-packages/django/db/models/sql/query.py", line 1349, in check_query_object_type
    raise ValueError(
ValueError: Cannot query "na2": Must be "UserProfile" instance.
Internal Server Error: /dashboard/schedules
Traceback (most recent call last):
  File "/usr/local/lib/python3.11/site-packages/django/core/handlers/exception.py", line 55, in inner
    response = get_response(request)
               ^^^^^^^^^^^^^^^^^^^^^
  File "/usr/local/lib/python3.11/site-packages/django/core/handlers/base.py", line 197, in _get_response
    response = wrapped_callback(request, *callback_args, **callback_kwargs)
               ^^^^^^^^^^^^^^^^^^^^^^^^^^^^^^^^^^^^^^^^^^^^^^^^^^^^^^^^^^^^
  File "/usr/local/lib/python3.11/site-packages/django/views/generic/base.py", line 105, in view
    return self.dispatch(request, *args, **kwargs)
           ^^^^^^^^^^^^^^^^^^^^^^^^^^^^^^^^^^^^^^^
  File "/usr/local/lib/python3.11/site-packages/django/contrib/auth/mixins.py", line 73, in dispatch
    return super().dispatch(request, *args, **kwargs)
           ^^^^^^^^^^^^^^^^^^^^^^^^^^^^^^^^^^^^^^^^^^
  File "/usr/local/lib/python3.11/site-packages/django/views/generic/base.py", line 144, in dispatch
    return handler(request, *args, **kwargs)
           ^^^^^^^^^^^^^^^^^^^^^^^^^^^^^^^^^
  File "/app/dashboard/views.py", line 831, in get
    return render(request, self.template_name)
           ^^^^^^^^^^^^^^^^^^^^^^^^^^^^^^^^^^^
  File "/usr/local/lib/python3.11/site-packages/django/shortcuts.py", line 25, in render
    content = loader.render_to_string(template_name, context, request, using=using)
              ^^^^^^^^^^^^^^^^^^^^^^^^^^^^^^^^^^^^^^^^^^^^^^^^^^^^^^^^^^^^^^^^^^^^^
  File "/usr/local/lib/python3.11/site-packages/django/template/loader.py", line 62, in render_to_string
    return template.render(context, request)
           ^^^^^^^^^^^^^^^^^^^^^^^^^^^^^^^^^
  File "/usr/local/lib/python3.11/site-packages/django/template/backends/django.py", line 107, in render
    return self.template.render(context)
           ^^^^^^^^^^^^^^^^^^^^^^^^^^^^^
  File "/usr/local/lib/python3.11/site-packages/django/template/base.py", line 171, in render
    return self._render(context)
           ^^^^^^^^^^^^^^^^^^^^^
  File "/usr/local/lib/python3.11/site-packages/django/test/utils.py", line 114, in instrumented_test_render
    return self.nodelist.render(context)
           ^^^^^^^^^^^^^^^^^^^^^^^^^^^^^
  File "/usr/local/lib/python3.11/site-packages/django/template/base.py", line 1016, in render
    return SafeString("".join([node.render_annotated(context) for node in self]))
                              ^^^^^^^^^^^^^^^^^^^^^^^^^^^^^^^^^^^^^^^^^^^^^^^^^
  File "/usr/local/lib/python3.11/site-packages/django/template/base.py", line 1016, in <listcomp>
    return SafeString("".join([node.render_annotated(context) for node in self]))
                               ^^^^^^^^^^^^^^^^^^^^^^^^^^^^^^
  File "/usr/local/lib/python3.11/site-packages/django/template/base.py", line 977, in render_annotated
    return self.render(context)
           ^^^^^^^^^^^^^^^^^^^^
  File "/usr/local/lib/python3.11/site-packages/django/template/loader_tags.py", line 56, in render
    result = self.nodelist.render(context)
             ^^^^^^^^^^^^^^^^^^^^^^^^^^^^^
  File "/usr/local/lib/python3.11/site-packages/django/template/base.py", line 1016, in render
    return SafeString("".join([node.render_annotated(context) for node in self]))
                              ^^^^^^^^^^^^^^^^^^^^^^^^^^^^^^^^^^^^^^^^^^^^^^^^^
  File "/usr/local/lib/python3.11/site-packages/django/template/base.py", line 1016, in <listcomp>
    return SafeString("".join([node.render_annotated(context) for node in self]))
                               ^^^^^^^^^^^^^^^^^^^^^^^^^^^^^^
  File "/usr/local/lib/python3.11/site-packages/django/template/base.py", line 977, in render_annotated
    return self.render(context)
           ^^^^^^^^^^^^^^^^^^^^
  File "/usr/local/lib/python3.11/site-packages/django/template/defaulttags.py", line 548, in render
    values = {key: val.resolve(context) for key, val in self.extra_context.items()}
             ^^^^^^^^^^^^^^^^^^^^^^^^^^^^^^^^^^^^^^^^^^^^^^^^^^^^^^^^^^^^^^^^^^^^^^
  File "/usr/local/lib/python3.11/site-packages/django/template/defaulttags.py", line 548, in <dictcomp>
    values = {key: val.resolve(context) for key, val in self.extra_context.items()}
                   ^^^^^^^^^^^^^^^^^^^^
  File "/usr/local/lib/python3.11/site-packages/django/template/base.py", line 749, in resolve
    new_obj = func(obj, *arg_vals)
              ^^^^^^^^^^^^^^^^^^^^
  File "/app/dashboard/templatetags/user_data.py", line 24, in get_schedules
    week1=weeks[0]
          ~~~~~^^^
IndexError: list index out of range
Internal Server Error: /
Traceback (most recent call last):
  File "C:\Users\gabri\OneDrive\Bureau\Python\projects\django website\.django\Lib\site-packages\django_redis\cache.py", line 29, in _decorator
    return method(self, *args, **kwargs)
  File "C:\Users\gabri\OneDrive\Bureau\Python\projects\django website\.django\Lib\site-packages\django_redis\cache.py", line 81, in set
    return self.client.set(*args, **kwargs)
           ~~~~~~~~~~~~~~~^^^^^^^^^^^^^^^^^
  File "C:\Users\gabri\OneDrive\Bureau\Python\projects\django website\.django\Lib\site-packages\django_redis\client\default.py", line 224, in set
    raise ConnectionInterrupted(connection=client) from e
django_redis.exceptions.ConnectionInterrupted: Redis ConnectionError: Error 11001 connecting to redis:6379. getaddrinfo failed.

During handling of the above exception, another exception occurred:

Traceback (most recent call last):
  File "C:\Users\gabri\OneDrive\Bureau\Python\projects\django website\.django\Lib\site-packages\django\core\handlers\exception.py", line 55, in inner
    response = get_response(request)
  File "C:\Users\gabri\OneDrive\Bureau\Python\projects\django website\.django\Lib\site-packages\django\core\handlers\base.py", line 220, in _get_response
    response = response.render()
  File "C:\Users\gabri\OneDrive\Bureau\Python\projects\django website\.django\Lib\site-packages\django\template\response.py", line 114, in render
    self.content = self.rendered_content
                   ^^^^^^^^^^^^^^^^^^^^^
  File "C:\Users\gabri\OneDrive\Bureau\Python\projects\django website\.django\Lib\site-packages\django\template\response.py", line 92, in rendered_content
    return template.render(context, self._request)
           ~~~~~~~~~~~~~~~^^^^^^^^^^^^^^^^^^^^^^^^
  File "C:\Users\gabri\OneDrive\Bureau\Python\projects\django website\.django\Lib\site-packages\django\template\backends\django.py", line 107, in render
    return self.template.render(context)
           ~~~~~~~~~~~~~~~~~~~~^^^^^^^^^
  File "C:\Users\gabri\OneDrive\Bureau\Python\projects\django website\.django\Lib\site-packages\django\template\base.py", line 169, in render
    with context.bind_template(self):
         ~~~~~~~~~~~~~~~~~~~~~^^^^^^
  File "C:\Users\gabri\AppData\Local\Programs\Python\Python313\Lib\contextlib.py", line 141, in __enter__
    return next(self.gen)
  File "C:\Users\gabri\OneDrive\Bureau\Python\projects\django website\.django\Lib\site-packages\debug_toolbar\panels\templates\panel.py", line 51, in _request_context_bind_template
    context = processor(self.request)
  File "C:\Users\gabri\OneDrive\Bureau\Python\projects\django website\app\dashboard\context_processor.py", line 4, in unread_messages_count
    if request.user.is_authenticated:
       ^^^^^^^^^^^^^^^^^^^^^^^^^^^^^
  File "C:\Users\gabri\OneDrive\Bureau\Python\projects\django website\.django\Lib\site-packages\django\utils\functional.py", line 251, in inner
    self._setup()
    ~~~~~~~~~~~^^
  File "C:\Users\gabri\OneDrive\Bureau\Python\projects\django website\.django\Lib\site-packages\django\utils\functional.py", line 404, in _setup
    self._wrapped = self._setupfunc()
                    ~~~~~~~~~~~~~~~^^
  File "C:\Users\gabri\OneDrive\Bureau\Python\projects\django website\.django\Lib\site-packages\django\contrib\auth\middleware.py", line 40, in <lambda>
    request.user = SimpleLazyObject(lambda: get_user(request))
                                            ~~~~~~~~^^^^^^^^^
  File "C:\Users\gabri\OneDrive\Bureau\Python\projects\django website\.django\Lib\site-packages\django\contrib\auth\middleware.py", line 20, in get_user
    request._cached_user = auth.get_user(request)
                           ~~~~~~~~~~~~~^^^^^^^^^
  File "C:\Users\gabri\OneDrive\Bureau\Python\projects\django website\.django\Lib\site-packages\django\contrib\auth\__init__.py", line 304, in get_user
    user_id = _get_user_session_key(request)
  File "C:\Users\gabri\OneDrive\Bureau\Python\projects\django website\.django\Lib\site-packages\django\contrib\auth\__init__.py", line 95, in _get_user_session_key
    return get_user_model()._meta.pk.to_python(request.session[SESSION_KEY])
                                               ~~~~~~~~~~~~~~~^^^^^^^^^^^^^
  File "C:\Users\gabri\OneDrive\Bureau\Python\projects\django website\.django\Lib\site-packages\django\contrib\sessions\backends\base.py", line 55, in __getitem__
    return self._session[key]
           ^^^^^^^^^^^^^
  File "C:\Users\gabri\OneDrive\Bureau\Python\projects\django website\.django\Lib\site-packages\django\contrib\sessions\backends\base.py", line 249, in _get_session
    self._session_cache = self.load()
                          ~~~~~~~~~^^
  File "C:\Users\gabri\OneDrive\Bureau\Python\projects\django website\.django\Lib\site-packages\django\contrib\sessions\backends\cached_db.py", line 46, in load
    self._cache.set(
    ~~~~~~~~~~~~~~~^
        self.cache_key, data, self.get_expiry_age(expiry=s.expire_date)
        ^^^^^^^^^^^^^^^^^^^^^^^^^^^^^^^^^^^^^^^^^^^^^^^^^^^^^^^^^^^^^^^
    )
    ^
  File "C:\Users\gabri\OneDrive\Bureau\Python\projects\django website\.django\Lib\site-packages\debug_toolbar\panels\cache.py", line 42, in wrapper
    return panel._record_call(cache, name, original_method, args, kwargs)
           ~~~~~~~~~~~~~~~~~~^^^^^^^^^^^^^^^^^^^^^^^^^^^^^^^^^^^^^^^^^^^^
  File "C:\Users\gabri\OneDrive\Bureau\Python\projects\django website\.django\Lib\site-packages\debug_toolbar\panels\cache.py", line 151, in _record_call
    value = original_method(*args, **kwargs)
  File "C:\Users\gabri\OneDrive\Bureau\Python\projects\django website\.django\Lib\site-packages\django_redis\cache.py", line 36, in _decorator
    raise e.__cause__  # noqa: B904
    ^^^^^^^^^^^^^^^^^
  File "C:\Users\gabri\OneDrive\Bureau\Python\projects\django website\.django\Lib\site-packages\django_redis\client\default.py", line 214, in set
    return bool(client.set(nkey, nvalue, nx=nx, px=timeout, xx=xx))
                ~~~~~~~~~~^^^^^^^^^^^^^^^^^^^^^^^^^^^^^^^^^^^^^^^^
  File "C:\Users\gabri\OneDrive\Bureau\Python\projects\django website\.django\Lib\site-packages\redis\commands\core.py", line 2305, in set
    return self.execute_command("SET", *pieces, **options)
           ~~~~~~~~~~~~~~~~~~~~^^^^^^^^^^^^^^^^^^^^^^^^^^^
  File "C:\Users\gabri\OneDrive\Bureau\Python\projects\django website\.django\Lib\site-packages\redis\client.py", line 621, in execute_command
    return self._execute_command(*args, **options)
           ~~~~~~~~~~~~~~~~~~~~~^^^^^^^^^^^^^^^^^^
  File "C:\Users\gabri\OneDrive\Bureau\Python\projects\django website\.django\Lib\site-packages\redis\client.py", line 627, in _execute_command
    conn = self.connection or pool.get_connection()
                              ~~~~~~~~~~~~~~~~~~~^^
  File "C:\Users\gabri\OneDrive\Bureau\Python\projects\django website\.django\Lib\site-packages\redis\utils.py", line 195, in wrapper
    return func(*args, **kwargs)
  File "C:\Users\gabri\OneDrive\Bureau\Python\projects\django website\.django\Lib\site-packages\redis\connection.py", line 1533, in get_connection
    connection.connect()
    ~~~~~~~~~~~~~~~~~~^^
  File "C:\Users\gabri\OneDrive\Bureau\Python\projects\django website\.django\Lib\site-packages\redis\connection.py", line 380, in connect
    self.connect_check_health(check_health=True)
    ~~~~~~~~~~~~~~~~~~~~~~~~~^^^^^^^^^^^^^^^^^^^
  File "C:\Users\gabri\OneDrive\Bureau\Python\projects\django website\.django\Lib\site-packages\redis\connection.py", line 397, in connect_check_health
    raise ConnectionError(self._error_message(e))
redis.exceptions.ConnectionError: Error 11001 connecting to redis:6379. getaddrinfo failed.
Internal Server Error: /
Traceback (most recent call last):
  File "C:\Users\gabri\OneDrive\Bureau\Python\projects\django website\.django\Lib\site-packages\django_redis\cache.py", line 29, in _decorator
    return method(self, *args, **kwargs)
  File "C:\Users\gabri\OneDrive\Bureau\Python\projects\django website\.django\Lib\site-packages\django_redis\cache.py", line 81, in set
    return self.client.set(*args, **kwargs)
           ~~~~~~~~~~~~~~~^^^^^^^^^^^^^^^^^
  File "C:\Users\gabri\OneDrive\Bureau\Python\projects\django website\.django\Lib\site-packages\django_redis\client\default.py", line 224, in set
    raise ConnectionInterrupted(connection=client) from e
django_redis.exceptions.ConnectionInterrupted: Redis ConnectionError: Error 11001 connecting to redis:6379. getaddrinfo failed.

During handling of the above exception, another exception occurred:

Traceback (most recent call last):
  File "C:\Users\gabri\OneDrive\Bureau\Python\projects\django website\.django\Lib\site-packages\django\core\handlers\exception.py", line 55, in inner
    response = get_response(request)
  File "C:\Users\gabri\OneDrive\Bureau\Python\projects\django website\.django\Lib\site-packages\django\core\handlers\base.py", line 220, in _get_response
    response = response.render()
  File "C:\Users\gabri\OneDrive\Bureau\Python\projects\django website\.django\Lib\site-packages\django\template\response.py", line 114, in render
    self.content = self.rendered_content
                   ^^^^^^^^^^^^^^^^^^^^^
  File "C:\Users\gabri\OneDrive\Bureau\Python\projects\django website\.django\Lib\site-packages\django\template\response.py", line 92, in rendered_content
    return template.render(context, self._request)
           ~~~~~~~~~~~~~~~^^^^^^^^^^^^^^^^^^^^^^^^
  File "C:\Users\gabri\OneDrive\Bureau\Python\projects\django website\.django\Lib\site-packages\django\template\backends\django.py", line 107, in render
    return self.template.render(context)
           ~~~~~~~~~~~~~~~~~~~~^^^^^^^^^
  File "C:\Users\gabri\OneDrive\Bureau\Python\projects\django website\.django\Lib\site-packages\django\template\base.py", line 169, in render
    with context.bind_template(self):
         ~~~~~~~~~~~~~~~~~~~~~^^^^^^
  File "C:\Users\gabri\AppData\Local\Programs\Python\Python313\Lib\contextlib.py", line 141, in __enter__
    return next(self.gen)
  File "C:\Users\gabri\OneDrive\Bureau\Python\projects\django website\.django\Lib\site-packages\debug_toolbar\panels\templates\panel.py", line 51, in _request_context_bind_template
    context = processor(self.request)
  File "C:\Users\gabri\OneDrive\Bureau\Python\projects\django website\app\dashboard\context_processor.py", line 4, in unread_messages_count
    if request.user.is_authenticated:
       ^^^^^^^^^^^^^^^^^^^^^^^^^^^^^
  File "C:\Users\gabri\OneDrive\Bureau\Python\projects\django website\.django\Lib\site-packages\django\utils\functional.py", line 251, in inner
    self._setup()
    ~~~~~~~~~~~^^
  File "C:\Users\gabri\OneDrive\Bureau\Python\projects\django website\.django\Lib\site-packages\django\utils\functional.py", line 404, in _setup
    self._wrapped = self._setupfunc()
                    ~~~~~~~~~~~~~~~^^
  File "C:\Users\gabri\OneDrive\Bureau\Python\projects\django website\.django\Lib\site-packages\django\contrib\auth\middleware.py", line 40, in <lambda>
    request.user = SimpleLazyObject(lambda: get_user(request))
                                            ~~~~~~~~^^^^^^^^^
  File "C:\Users\gabri\OneDrive\Bureau\Python\projects\django website\.django\Lib\site-packages\django\contrib\auth\middleware.py", line 20, in get_user
    request._cached_user = auth.get_user(request)
                           ~~~~~~~~~~~~~^^^^^^^^^
  File "C:\Users\gabri\OneDrive\Bureau\Python\projects\django website\.django\Lib\site-packages\django\contrib\auth\__init__.py", line 304, in get_user
    user_id = _get_user_session_key(request)
  File "C:\Users\gabri\OneDrive\Bureau\Python\projects\django website\.django\Lib\site-packages\django\contrib\auth\__init__.py", line 95, in _get_user_session_key
    return get_user_model()._meta.pk.to_python(request.session[SESSION_KEY])
                                               ~~~~~~~~~~~~~~~^^^^^^^^^^^^^
  File "C:\Users\gabri\OneDrive\Bureau\Python\projects\django website\.django\Lib\site-packages\django\contrib\sessions\backends\base.py", line 55, in __getitem__
    return self._session[key]
           ^^^^^^^^^^^^^
  File "C:\Users\gabri\OneDrive\Bureau\Python\projects\django website\.django\Lib\site-packages\django\contrib\sessions\backends\base.py", line 249, in _get_session
    self._session_cache = self.load()
                          ~~~~~~~~~^^
  File "C:\Users\gabri\OneDrive\Bureau\Python\projects\django website\.django\Lib\site-packages\django\contrib\sessions\backends\cached_db.py", line 46, in load
    self._cache.set(
    ~~~~~~~~~~~~~~~^
        self.cache_key, data, self.get_expiry_age(expiry=s.expire_date)
        ^^^^^^^^^^^^^^^^^^^^^^^^^^^^^^^^^^^^^^^^^^^^^^^^^^^^^^^^^^^^^^^
    )
    ^
  File "C:\Users\gabri\OneDrive\Bureau\Python\projects\django website\.django\Lib\site-packages\debug_toolbar\panels\cache.py", line 42, in wrapper
    return panel._record_call(cache, name, original_method, args, kwargs)
           ~~~~~~~~~~~~~~~~~~^^^^^^^^^^^^^^^^^^^^^^^^^^^^^^^^^^^^^^^^^^^^
  File "C:\Users\gabri\OneDrive\Bureau\Python\projects\django website\.django\Lib\site-packages\debug_toolbar\panels\cache.py", line 151, in _record_call
    value = original_method(*args, **kwargs)
  File "C:\Users\gabri\OneDrive\Bureau\Python\projects\django website\.django\Lib\site-packages\django_redis\cache.py", line 36, in _decorator
    raise e.__cause__  # noqa: B904
    ^^^^^^^^^^^^^^^^^
  File "C:\Users\gabri\OneDrive\Bureau\Python\projects\django website\.django\Lib\site-packages\django_redis\client\default.py", line 214, in set
    return bool(client.set(nkey, nvalue, nx=nx, px=timeout, xx=xx))
                ~~~~~~~~~~^^^^^^^^^^^^^^^^^^^^^^^^^^^^^^^^^^^^^^^^
  File "C:\Users\gabri\OneDrive\Bureau\Python\projects\django website\.django\Lib\site-packages\redis\commands\core.py", line 2305, in set
    return self.execute_command("SET", *pieces, **options)
           ~~~~~~~~~~~~~~~~~~~~^^^^^^^^^^^^^^^^^^^^^^^^^^^
  File "C:\Users\gabri\OneDrive\Bureau\Python\projects\django website\.django\Lib\site-packages\redis\client.py", line 621, in execute_command
    return self._execute_command(*args, **options)
           ~~~~~~~~~~~~~~~~~~~~~^^^^^^^^^^^^^^^^^^
  File "C:\Users\gabri\OneDrive\Bureau\Python\projects\django website\.django\Lib\site-packages\redis\client.py", line 627, in _execute_command
    conn = self.connection or pool.get_connection()
                              ~~~~~~~~~~~~~~~~~~~^^
  File "C:\Users\gabri\OneDrive\Bureau\Python\projects\django website\.django\Lib\site-packages\redis\utils.py", line 195, in wrapper
    return func(*args, **kwargs)
  File "C:\Users\gabri\OneDrive\Bureau\Python\projects\django website\.django\Lib\site-packages\redis\connection.py", line 1533, in get_connection
    connection.connect()
    ~~~~~~~~~~~~~~~~~~^^
  File "C:\Users\gabri\OneDrive\Bureau\Python\projects\django website\.django\Lib\site-packages\redis\connection.py", line 380, in connect
    self.connect_check_health(check_health=True)
    ~~~~~~~~~~~~~~~~~~~~~~~~~^^^^^^^^^^^^^^^^^^^
  File "C:\Users\gabri\OneDrive\Bureau\Python\projects\django website\.django\Lib\site-packages\redis\connection.py", line 397, in connect_check_health
    raise ConnectionError(self._error_message(e))
redis.exceptions.ConnectionError: Error 11001 connecting to redis:6379. getaddrinfo failed.
Internal Server Error: /
Traceback (most recent call last):
  File "C:\Users\gabri\OneDrive\Bureau\Python\projects\django website\.django\Lib\site-packages\django_redis\cache.py", line 29, in _decorator
    return method(self, *args, **kwargs)
  File "C:\Users\gabri\OneDrive\Bureau\Python\projects\django website\.django\Lib\site-packages\django_redis\cache.py", line 81, in set
    return self.client.set(*args, **kwargs)
           ~~~~~~~~~~~~~~~^^^^^^^^^^^^^^^^^
  File "C:\Users\gabri\OneDrive\Bureau\Python\projects\django website\.django\Lib\site-packages\django_redis\client\default.py", line 224, in set
    raise ConnectionInterrupted(connection=client) from e
django_redis.exceptions.ConnectionInterrupted: Redis ConnectionError: Error 11001 connecting to redis:6379. getaddrinfo failed.

During handling of the above exception, another exception occurred:

Traceback (most recent call last):
  File "C:\Users\gabri\OneDrive\Bureau\Python\projects\django website\.django\Lib\site-packages\django\core\handlers\exception.py", line 55, in inner
    response = get_response(request)
  File "C:\Users\gabri\OneDrive\Bureau\Python\projects\django website\.django\Lib\site-packages\django\core\handlers\base.py", line 220, in _get_response
    response = response.render()
  File "C:\Users\gabri\OneDrive\Bureau\Python\projects\django website\.django\Lib\site-packages\django\template\response.py", line 114, in render
    self.content = self.rendered_content
                   ^^^^^^^^^^^^^^^^^^^^^
  File "C:\Users\gabri\OneDrive\Bureau\Python\projects\django website\.django\Lib\site-packages\django\template\response.py", line 92, in rendered_content
    return template.render(context, self._request)
           ~~~~~~~~~~~~~~~^^^^^^^^^^^^^^^^^^^^^^^^
  File "C:\Users\gabri\OneDrive\Bureau\Python\projects\django website\.django\Lib\site-packages\django\template\backends\django.py", line 107, in render
    return self.template.render(context)
           ~~~~~~~~~~~~~~~~~~~~^^^^^^^^^
  File "C:\Users\gabri\OneDrive\Bureau\Python\projects\django website\.django\Lib\site-packages\django\template\base.py", line 169, in render
    with context.bind_template(self):
         ~~~~~~~~~~~~~~~~~~~~~^^^^^^
  File "C:\Users\gabri\AppData\Local\Programs\Python\Python313\Lib\contextlib.py", line 141, in __enter__
    return next(self.gen)
  File "C:\Users\gabri\OneDrive\Bureau\Python\projects\django website\.django\Lib\site-packages\debug_toolbar\panels\templates\panel.py", line 51, in _request_context_bind_template
    context = processor(self.request)
  File "C:\Users\gabri\OneDrive\Bureau\Python\projects\django website\app\dashboard\context_processor.py", line 4, in unread_messages_count
    if request.user.is_authenticated:
       ^^^^^^^^^^^^^^^^^^^^^^^^^^^^^
  File "C:\Users\gabri\OneDrive\Bureau\Python\projects\django website\.django\Lib\site-packages\django\utils\functional.py", line 251, in inner
    self._setup()
    ~~~~~~~~~~~^^
  File "C:\Users\gabri\OneDrive\Bureau\Python\projects\django website\.django\Lib\site-packages\django\utils\functional.py", line 404, in _setup
    self._wrapped = self._setupfunc()
                    ~~~~~~~~~~~~~~~^^
  File "C:\Users\gabri\OneDrive\Bureau\Python\projects\django website\.django\Lib\site-packages\django\contrib\auth\middleware.py", line 40, in <lambda>
    request.user = SimpleLazyObject(lambda: get_user(request))
                                            ~~~~~~~~^^^^^^^^^
  File "C:\Users\gabri\OneDrive\Bureau\Python\projects\django website\.django\Lib\site-packages\django\contrib\auth\middleware.py", line 20, in get_user
    request._cached_user = auth.get_user(request)
                           ~~~~~~~~~~~~~^^^^^^^^^
  File "C:\Users\gabri\OneDrive\Bureau\Python\projects\django website\.django\Lib\site-packages\django\contrib\auth\__init__.py", line 304, in get_user
    user_id = _get_user_session_key(request)
  File "C:\Users\gabri\OneDrive\Bureau\Python\projects\django website\.django\Lib\site-packages\django\contrib\auth\__init__.py", line 95, in _get_user_session_key
    return get_user_model()._meta.pk.to_python(request.session[SESSION_KEY])
                                               ~~~~~~~~~~~~~~~^^^^^^^^^^^^^
  File "C:\Users\gabri\OneDrive\Bureau\Python\projects\django website\.django\Lib\site-packages\django\contrib\sessions\backends\base.py", line 55, in __getitem__
    return self._session[key]
           ^^^^^^^^^^^^^
  File "C:\Users\gabri\OneDrive\Bureau\Python\projects\django website\.django\Lib\site-packages\django\contrib\sessions\backends\base.py", line 249, in _get_session
    self._session_cache = self.load()
                          ~~~~~~~~~^^
  File "C:\Users\gabri\OneDrive\Bureau\Python\projects\django website\.django\Lib\site-packages\django\contrib\sessions\backends\cached_db.py", line 46, in load
    self._cache.set(
    ~~~~~~~~~~~~~~~^
        self.cache_key, data, self.get_expiry_age(expiry=s.expire_date)
        ^^^^^^^^^^^^^^^^^^^^^^^^^^^^^^^^^^^^^^^^^^^^^^^^^^^^^^^^^^^^^^^
    )
    ^
  File "C:\Users\gabri\OneDrive\Bureau\Python\projects\django website\.django\Lib\site-packages\debug_toolbar\panels\cache.py", line 42, in wrapper
    return panel._record_call(cache, name, original_method, args, kwargs)
           ~~~~~~~~~~~~~~~~~~^^^^^^^^^^^^^^^^^^^^^^^^^^^^^^^^^^^^^^^^^^^^
  File "C:\Users\gabri\OneDrive\Bureau\Python\projects\django website\.django\Lib\site-packages\debug_toolbar\panels\cache.py", line 151, in _record_call
    value = original_method(*args, **kwargs)
  File "C:\Users\gabri\OneDrive\Bureau\Python\projects\django website\.django\Lib\site-packages\django_redis\cache.py", line 36, in _decorator
    raise e.__cause__  # noqa: B904
    ^^^^^^^^^^^^^^^^^
  File "C:\Users\gabri\OneDrive\Bureau\Python\projects\django website\.django\Lib\site-packages\django_redis\client\default.py", line 214, in set
    return bool(client.set(nkey, nvalue, nx=nx, px=timeout, xx=xx))
                ~~~~~~~~~~^^^^^^^^^^^^^^^^^^^^^^^^^^^^^^^^^^^^^^^^
  File "C:\Users\gabri\OneDrive\Bureau\Python\projects\django website\.django\Lib\site-packages\redis\commands\core.py", line 2305, in set
    return self.execute_command("SET", *pieces, **options)
           ~~~~~~~~~~~~~~~~~~~~^^^^^^^^^^^^^^^^^^^^^^^^^^^
  File "C:\Users\gabri\OneDrive\Bureau\Python\projects\django website\.django\Lib\site-packages\redis\client.py", line 621, in execute_command
    return self._execute_command(*args, **options)
           ~~~~~~~~~~~~~~~~~~~~~^^^^^^^^^^^^^^^^^^
  File "C:\Users\gabri\OneDrive\Bureau\Python\projects\django website\.django\Lib\site-packages\redis\client.py", line 627, in _execute_command
    conn = self.connection or pool.get_connection()
                              ~~~~~~~~~~~~~~~~~~~^^
  File "C:\Users\gabri\OneDrive\Bureau\Python\projects\django website\.django\Lib\site-packages\redis\utils.py", line 195, in wrapper
    return func(*args, **kwargs)
  File "C:\Users\gabri\OneDrive\Bureau\Python\projects\django website\.django\Lib\site-packages\redis\connection.py", line 1533, in get_connection
    connection.connect()
    ~~~~~~~~~~~~~~~~~~^^
  File "C:\Users\gabri\OneDrive\Bureau\Python\projects\django website\.django\Lib\site-packages\redis\connection.py", line 380, in connect
    self.connect_check_health(check_health=True)
    ~~~~~~~~~~~~~~~~~~~~~~~~~^^^^^^^^^^^^^^^^^^^
  File "C:\Users\gabri\OneDrive\Bureau\Python\projects\django website\.django\Lib\site-packages\redis\connection.py", line 397, in connect_check_health
    raise ConnectionError(self._error_message(e))
redis.exceptions.ConnectionError: Error 11001 connecting to redis:6379. getaddrinfo failed.
Internal Server Error: /
Traceback (most recent call last):
  File "C:\Users\gabri\OneDrive\Bureau\Python\projects\django website\.django\Lib\site-packages\django_redis\cache.py", line 29, in _decorator
    return method(self, *args, **kwargs)
  File "C:\Users\gabri\OneDrive\Bureau\Python\projects\django website\.django\Lib\site-packages\django_redis\cache.py", line 81, in set
    return self.client.set(*args, **kwargs)
           ~~~~~~~~~~~~~~~^^^^^^^^^^^^^^^^^
  File "C:\Users\gabri\OneDrive\Bureau\Python\projects\django website\.django\Lib\site-packages\django_redis\client\default.py", line 224, in set
    raise ConnectionInterrupted(connection=client) from e
django_redis.exceptions.ConnectionInterrupted: Redis ConnectionError: Error 11001 connecting to redis:6379. getaddrinfo failed.

During handling of the above exception, another exception occurred:

Traceback (most recent call last):
  File "C:\Users\gabri\OneDrive\Bureau\Python\projects\django website\.django\Lib\site-packages\django\core\handlers\exception.py", line 55, in inner
    response = get_response(request)
  File "C:\Users\gabri\OneDrive\Bureau\Python\projects\django website\.django\Lib\site-packages\django\core\handlers\base.py", line 220, in _get_response
    response = response.render()
  File "C:\Users\gabri\OneDrive\Bureau\Python\projects\django website\.django\Lib\site-packages\django\template\response.py", line 114, in render
    self.content = self.rendered_content
                   ^^^^^^^^^^^^^^^^^^^^^
  File "C:\Users\gabri\OneDrive\Bureau\Python\projects\django website\.django\Lib\site-packages\django\template\response.py", line 92, in rendered_content
    return template.render(context, self._request)
           ~~~~~~~~~~~~~~~^^^^^^^^^^^^^^^^^^^^^^^^
  File "C:\Users\gabri\OneDrive\Bureau\Python\projects\django website\.django\Lib\site-packages\django\template\backends\django.py", line 107, in render
    return self.template.render(context)
           ~~~~~~~~~~~~~~~~~~~~^^^^^^^^^
  File "C:\Users\gabri\OneDrive\Bureau\Python\projects\django website\.django\Lib\site-packages\django\template\base.py", line 169, in render
    with context.bind_template(self):
         ~~~~~~~~~~~~~~~~~~~~~^^^^^^
  File "C:\Users\gabri\AppData\Local\Programs\Python\Python313\Lib\contextlib.py", line 141, in __enter__
    return next(self.gen)
  File "C:\Users\gabri\OneDrive\Bureau\Python\projects\django website\.django\Lib\site-packages\debug_toolbar\panels\templates\panel.py", line 51, in _request_context_bind_template
    context = processor(self.request)
  File "C:\Users\gabri\OneDrive\Bureau\Python\projects\django website\app\dashboard\context_processor.py", line 4, in unread_messages_count
    if request.user.is_authenticated:
       ^^^^^^^^^^^^^^^^^^^^^^^^^^^^^
  File "C:\Users\gabri\OneDrive\Bureau\Python\projects\django website\.django\Lib\site-packages\django\utils\functional.py", line 251, in inner
    self._setup()
    ~~~~~~~~~~~^^
  File "C:\Users\gabri\OneDrive\Bureau\Python\projects\django website\.django\Lib\site-packages\django\utils\functional.py", line 404, in _setup
    self._wrapped = self._setupfunc()
                    ~~~~~~~~~~~~~~~^^
  File "C:\Users\gabri\OneDrive\Bureau\Python\projects\django website\.django\Lib\site-packages\django\contrib\auth\middleware.py", line 40, in <lambda>
    request.user = SimpleLazyObject(lambda: get_user(request))
                                            ~~~~~~~~^^^^^^^^^
  File "C:\Users\gabri\OneDrive\Bureau\Python\projects\django website\.django\Lib\site-packages\django\contrib\auth\middleware.py", line 20, in get_user
    request._cached_user = auth.get_user(request)
                           ~~~~~~~~~~~~~^^^^^^^^^
  File "C:\Users\gabri\OneDrive\Bureau\Python\projects\django website\.django\Lib\site-packages\django\contrib\auth\__init__.py", line 304, in get_user
    user_id = _get_user_session_key(request)
  File "C:\Users\gabri\OneDrive\Bureau\Python\projects\django website\.django\Lib\site-packages\django\contrib\auth\__init__.py", line 95, in _get_user_session_key
    return get_user_model()._meta.pk.to_python(request.session[SESSION_KEY])
                                               ~~~~~~~~~~~~~~~^^^^^^^^^^^^^
  File "C:\Users\gabri\OneDrive\Bureau\Python\projects\django website\.django\Lib\site-packages\django\contrib\sessions\backends\base.py", line 55, in __getitem__
    return self._session[key]
           ^^^^^^^^^^^^^
  File "C:\Users\gabri\OneDrive\Bureau\Python\projects\django website\.django\Lib\site-packages\django\contrib\sessions\backends\base.py", line 249, in _get_session
    self._session_cache = self.load()
                          ~~~~~~~~~^^
  File "C:\Users\gabri\OneDrive\Bureau\Python\projects\django website\.django\Lib\site-packages\django\contrib\sessions\backends\cached_db.py", line 46, in load
    self._cache.set(
    ~~~~~~~~~~~~~~~^
        self.cache_key, data, self.get_expiry_age(expiry=s.expire_date)
        ^^^^^^^^^^^^^^^^^^^^^^^^^^^^^^^^^^^^^^^^^^^^^^^^^^^^^^^^^^^^^^^
    )
    ^
  File "C:\Users\gabri\OneDrive\Bureau\Python\projects\django website\.django\Lib\site-packages\debug_toolbar\panels\cache.py", line 42, in wrapper
    return panel._record_call(cache, name, original_method, args, kwargs)
           ~~~~~~~~~~~~~~~~~~^^^^^^^^^^^^^^^^^^^^^^^^^^^^^^^^^^^^^^^^^^^^
  File "C:\Users\gabri\OneDrive\Bureau\Python\projects\django website\.django\Lib\site-packages\debug_toolbar\panels\cache.py", line 151, in _record_call
    value = original_method(*args, **kwargs)
  File "C:\Users\gabri\OneDrive\Bureau\Python\projects\django website\.django\Lib\site-packages\django_redis\cache.py", line 36, in _decorator
    raise e.__cause__  # noqa: B904
    ^^^^^^^^^^^^^^^^^
  File "C:\Users\gabri\OneDrive\Bureau\Python\projects\django website\.django\Lib\site-packages\django_redis\client\default.py", line 214, in set
    return bool(client.set(nkey, nvalue, nx=nx, px=timeout, xx=xx))
                ~~~~~~~~~~^^^^^^^^^^^^^^^^^^^^^^^^^^^^^^^^^^^^^^^^
  File "C:\Users\gabri\OneDrive\Bureau\Python\projects\django website\.django\Lib\site-packages\redis\commands\core.py", line 2305, in set
    return self.execute_command("SET", *pieces, **options)
           ~~~~~~~~~~~~~~~~~~~~^^^^^^^^^^^^^^^^^^^^^^^^^^^
  File "C:\Users\gabri\OneDrive\Bureau\Python\projects\django website\.django\Lib\site-packages\redis\client.py", line 621, in execute_command
    return self._execute_command(*args, **options)
           ~~~~~~~~~~~~~~~~~~~~~^^^^^^^^^^^^^^^^^^
  File "C:\Users\gabri\OneDrive\Bureau\Python\projects\django website\.django\Lib\site-packages\redis\client.py", line 627, in _execute_command
    conn = self.connection or pool.get_connection()
                              ~~~~~~~~~~~~~~~~~~~^^
  File "C:\Users\gabri\OneDrive\Bureau\Python\projects\django website\.django\Lib\site-packages\redis\utils.py", line 195, in wrapper
    return func(*args, **kwargs)
  File "C:\Users\gabri\OneDrive\Bureau\Python\projects\django website\.django\Lib\site-packages\redis\connection.py", line 1533, in get_connection
    connection.connect()
    ~~~~~~~~~~~~~~~~~~^^
  File "C:\Users\gabri\OneDrive\Bureau\Python\projects\django website\.django\Lib\site-packages\redis\connection.py", line 380, in connect
    self.connect_check_health(check_health=True)
    ~~~~~~~~~~~~~~~~~~~~~~~~~^^^^^^^^^^^^^^^^^^^
  File "C:\Users\gabri\OneDrive\Bureau\Python\projects\django website\.django\Lib\site-packages\redis\connection.py", line 397, in connect_check_health
    raise ConnectionError(self._error_message(e))
redis.exceptions.ConnectionError: Error 11001 connecting to redis:6379. getaddrinfo failed.
Internal Server Error: /
Traceback (most recent call last):
  File "C:\Users\gabri\OneDrive\Bureau\Python\projects\django website\.django\Lib\site-packages\django_redis\cache.py", line 29, in _decorator
    return method(self, *args, **kwargs)
  File "C:\Users\gabri\OneDrive\Bureau\Python\projects\django website\.django\Lib\site-packages\django_redis\cache.py", line 81, in set
    return self.client.set(*args, **kwargs)
           ~~~~~~~~~~~~~~~^^^^^^^^^^^^^^^^^
  File "C:\Users\gabri\OneDrive\Bureau\Python\projects\django website\.django\Lib\site-packages\django_redis\client\default.py", line 224, in set
    raise ConnectionInterrupted(connection=client) from e
django_redis.exceptions.ConnectionInterrupted: Redis ConnectionError: Error 11001 connecting to redis:6379. getaddrinfo failed.

During handling of the above exception, another exception occurred:

Traceback (most recent call last):
  File "C:\Users\gabri\OneDrive\Bureau\Python\projects\django website\.django\Lib\site-packages\django\core\handlers\exception.py", line 55, in inner
    response = get_response(request)
  File "C:\Users\gabri\OneDrive\Bureau\Python\projects\django website\.django\Lib\site-packages\debug_toolbar\middleware.py", line 145, in __call__
    return self._postprocess(request, response, toolbar)
           ~~~~~~~~~~~~~~~~~^^^^^^^^^^^^^^^^^^^^^^^^^^^^
  File "C:\Users\gabri\OneDrive\Bureau\Python\projects\django website\.django\Lib\site-packages\debug_toolbar\middleware.py", line 182, in _postprocess
    panel.generate_stats(request, response)
    ~~~~~~~~~~~~~~~~~~~~^^^^^^^^^^^^^^^^^^^
  File "C:\Users\gabri\OneDrive\Bureau\Python\projects\django website\.django\Lib\site-packages\debug_toolbar\panels\request.py", line 62, in generate_stats
    session_data = dict(request.session)
  File "C:\Users\gabri\OneDrive\Bureau\Python\projects\django website\.django\Lib\site-packages\django\contrib\sessions\backends\base.py", line 160, in keys
    return self._session.keys()
           ^^^^^^^^^^^^^
  File "C:\Users\gabri\OneDrive\Bureau\Python\projects\django website\.django\Lib\site-packages\django\contrib\sessions\backends\base.py", line 249, in _get_session
    self._session_cache = self.load()
                          ~~~~~~~~~^^
  File "C:\Users\gabri\OneDrive\Bureau\Python\projects\django website\.django\Lib\site-packages\django\contrib\sessions\backends\cached_db.py", line 46, in load
    self._cache.set(
    ~~~~~~~~~~~~~~~^
        self.cache_key, data, self.get_expiry_age(expiry=s.expire_date)
        ^^^^^^^^^^^^^^^^^^^^^^^^^^^^^^^^^^^^^^^^^^^^^^^^^^^^^^^^^^^^^^^
    )
    ^
  File "C:\Users\gabri\OneDrive\Bureau\Python\projects\django website\.django\Lib\site-packages\debug_toolbar\panels\cache.py", line 40, in wrapper
    return original_method(*args, **kwargs)
  File "C:\Users\gabri\OneDrive\Bureau\Python\projects\django website\.django\Lib\site-packages\django_redis\cache.py", line 36, in _decorator
    raise e.__cause__  # noqa: B904
    ^^^^^^^^^^^^^^^^^
  File "C:\Users\gabri\OneDrive\Bureau\Python\projects\django website\.django\Lib\site-packages\django_redis\client\default.py", line 214, in set
    return bool(client.set(nkey, nvalue, nx=nx, px=timeout, xx=xx))
                ~~~~~~~~~~^^^^^^^^^^^^^^^^^^^^^^^^^^^^^^^^^^^^^^^^
  File "C:\Users\gabri\OneDrive\Bureau\Python\projects\django website\.django\Lib\site-packages\redis\commands\core.py", line 2305, in set
    return self.execute_command("SET", *pieces, **options)
           ~~~~~~~~~~~~~~~~~~~~^^^^^^^^^^^^^^^^^^^^^^^^^^^
  File "C:\Users\gabri\OneDrive\Bureau\Python\projects\django website\.django\Lib\site-packages\redis\client.py", line 621, in execute_command
    return self._execute_command(*args, **options)
           ~~~~~~~~~~~~~~~~~~~~~^^^^^^^^^^^^^^^^^^
  File "C:\Users\gabri\OneDrive\Bureau\Python\projects\django website\.django\Lib\site-packages\redis\client.py", line 627, in _execute_command
    conn = self.connection or pool.get_connection()
                              ~~~~~~~~~~~~~~~~~~~^^
  File "C:\Users\gabri\OneDrive\Bureau\Python\projects\django website\.django\Lib\site-packages\redis\utils.py", line 195, in wrapper
    return func(*args, **kwargs)
  File "C:\Users\gabri\OneDrive\Bureau\Python\projects\django website\.django\Lib\site-packages\redis\connection.py", line 1533, in get_connection
    connection.connect()
    ~~~~~~~~~~~~~~~~~~^^
  File "C:\Users\gabri\OneDrive\Bureau\Python\projects\django website\.django\Lib\site-packages\redis\connection.py", line 380, in connect
    self.connect_check_health(check_health=True)
    ~~~~~~~~~~~~~~~~~~~~~~~~~^^^^^^^^^^^^^^^^^^^
  File "C:\Users\gabri\OneDrive\Bureau\Python\projects\django website\.django\Lib\site-packages\redis\connection.py", line 397, in connect_check_health
    raise ConnectionError(self._error_message(e))
redis.exceptions.ConnectionError: Error 11001 connecting to redis:6379. getaddrinfo failed.
Internal Server Error: /
Traceback (most recent call last):
  File "C:\Users\gabri\OneDrive\Bureau\Python\projects\django website\.django\Lib\site-packages\django_redis\cache.py", line 29, in _decorator
    return method(self, *args, **kwargs)
  File "C:\Users\gabri\OneDrive\Bureau\Python\projects\django website\.django\Lib\site-packages\django_redis\cache.py", line 81, in set
    return self.client.set(*args, **kwargs)
           ~~~~~~~~~~~~~~~^^^^^^^^^^^^^^^^^
  File "C:\Users\gabri\OneDrive\Bureau\Python\projects\django website\.django\Lib\site-packages\django_redis\client\default.py", line 224, in set
    raise ConnectionInterrupted(connection=client) from e
django_redis.exceptions.ConnectionInterrupted: Redis ConnectionError: Error 11001 connecting to redis:6379. getaddrinfo failed.

During handling of the above exception, another exception occurred:

Traceback (most recent call last):
  File "C:\Users\gabri\OneDrive\Bureau\Python\projects\django website\.django\Lib\site-packages\django\core\handlers\exception.py", line 55, in inner
    response = get_response(request)
  File "C:\Users\gabri\OneDrive\Bureau\Python\projects\django website\.django\Lib\site-packages\debug_toolbar\middleware.py", line 145, in __call__
    return self._postprocess(request, response, toolbar)
           ~~~~~~~~~~~~~~~~~^^^^^^^^^^^^^^^^^^^^^^^^^^^^
  File "C:\Users\gabri\OneDrive\Bureau\Python\projects\django website\.django\Lib\site-packages\debug_toolbar\middleware.py", line 182, in _postprocess
    panel.generate_stats(request, response)
    ~~~~~~~~~~~~~~~~~~~~^^^^^^^^^^^^^^^^^^^
  File "C:\Users\gabri\OneDrive\Bureau\Python\projects\django website\.django\Lib\site-packages\debug_toolbar\panels\request.py", line 62, in generate_stats
    session_data = dict(request.session)
  File "C:\Users\gabri\OneDrive\Bureau\Python\projects\django website\.django\Lib\site-packages\django\contrib\sessions\backends\base.py", line 160, in keys
    return self._session.keys()
           ^^^^^^^^^^^^^
  File "C:\Users\gabri\OneDrive\Bureau\Python\projects\django website\.django\Lib\site-packages\django\contrib\sessions\backends\base.py", line 249, in _get_session
    self._session_cache = self.load()
                          ~~~~~~~~~^^
  File "C:\Users\gabri\OneDrive\Bureau\Python\projects\django website\.django\Lib\site-packages\django\contrib\sessions\backends\cached_db.py", line 46, in load
    self._cache.set(
    ~~~~~~~~~~~~~~~^
        self.cache_key, data, self.get_expiry_age(expiry=s.expire_date)
        ^^^^^^^^^^^^^^^^^^^^^^^^^^^^^^^^^^^^^^^^^^^^^^^^^^^^^^^^^^^^^^^
    )
    ^
  File "C:\Users\gabri\OneDrive\Bureau\Python\projects\django website\.django\Lib\site-packages\debug_toolbar\panels\cache.py", line 40, in wrapper
    return original_method(*args, **kwargs)
  File "C:\Users\gabri\OneDrive\Bureau\Python\projects\django website\.django\Lib\site-packages\django_redis\cache.py", line 36, in _decorator
    raise e.__cause__  # noqa: B904
    ^^^^^^^^^^^^^^^^^
  File "C:\Users\gabri\OneDrive\Bureau\Python\projects\django website\.django\Lib\site-packages\django_redis\client\default.py", line 214, in set
    return bool(client.set(nkey, nvalue, nx=nx, px=timeout, xx=xx))
                ~~~~~~~~~~^^^^^^^^^^^^^^^^^^^^^^^^^^^^^^^^^^^^^^^^
  File "C:\Users\gabri\OneDrive\Bureau\Python\projects\django website\.django\Lib\site-packages\redis\commands\core.py", line 2305, in set
    return self.execute_command("SET", *pieces, **options)
           ~~~~~~~~~~~~~~~~~~~~^^^^^^^^^^^^^^^^^^^^^^^^^^^
  File "C:\Users\gabri\OneDrive\Bureau\Python\projects\django website\.django\Lib\site-packages\redis\client.py", line 621, in execute_command
    return self._execute_command(*args, **options)
           ~~~~~~~~~~~~~~~~~~~~~^^^^^^^^^^^^^^^^^^
  File "C:\Users\gabri\OneDrive\Bureau\Python\projects\django website\.django\Lib\site-packages\redis\client.py", line 627, in _execute_command
    conn = self.connection or pool.get_connection()
                              ~~~~~~~~~~~~~~~~~~~^^
  File "C:\Users\gabri\OneDrive\Bureau\Python\projects\django website\.django\Lib\site-packages\redis\utils.py", line 195, in wrapper
    return func(*args, **kwargs)
  File "C:\Users\gabri\OneDrive\Bureau\Python\projects\django website\.django\Lib\site-packages\redis\connection.py", line 1533, in get_connection
    connection.connect()
    ~~~~~~~~~~~~~~~~~~^^
  File "C:\Users\gabri\OneDrive\Bureau\Python\projects\django website\.django\Lib\site-packages\redis\connection.py", line 380, in connect
    self.connect_check_health(check_health=True)
    ~~~~~~~~~~~~~~~~~~~~~~~~~^^^^^^^^^^^^^^^^^^^
  File "C:\Users\gabri\OneDrive\Bureau\Python\projects\django website\.django\Lib\site-packages\redis\connection.py", line 397, in connect_check_health
    raise ConnectionError(self._error_message(e))
redis.exceptions.ConnectionError: Error 11001 connecting to redis:6379. getaddrinfo failed.
Internal Server Error: /dashboard/home/
Traceback (most recent call last):
  File "C:\Users\gabri\OneDrive\Bureau\Python\projects\django website\.django\Lib\site-packages\django_redis\cache.py", line 29, in _decorator
    return method(self, *args, **kwargs)
  File "C:\Users\gabri\OneDrive\Bureau\Python\projects\django website\.django\Lib\site-packages\django_redis\cache.py", line 99, in _get
    return self.client.get(key, default=default, version=version, client=client)
           ~~~~~~~~~~~~~~~^^^^^^^^^^^^^^^^^^^^^^^^^^^^^^^^^^^^^^^^^^^^^^^^^^^^^^
  File "C:\Users\gabri\OneDrive\Bureau\Python\projects\django website\.django\Lib\site-packages\django_redis\client\default.py", line 300, in get
    raise ConnectionInterrupted(connection=client) from e
django_redis.exceptions.ConnectionInterrupted: Redis TimeoutError: Timeout connecting to server

During handling of the above exception, another exception occurred:

Traceback (most recent call last):
  File "C:\Users\gabri\OneDrive\Bureau\Python\projects\django website\.django\Lib\site-packages\django\core\handlers\exception.py", line 55, in inner
    response = get_response(request)
  File "C:\Users\gabri\OneDrive\Bureau\Python\projects\django website\.django\Lib\site-packages\django\core\handlers\base.py", line 197, in _get_response
    response = wrapped_callback(request, *callback_args, **callback_kwargs)
  File "C:\Users\gabri\OneDrive\Bureau\Python\projects\django website\.django\Lib\site-packages\django\views\generic\base.py", line 105, in view
    return self.dispatch(request, *args, **kwargs)
           ~~~~~~~~~~~~~^^^^^^^^^^^^^^^^^^^^^^^^^^
  File "C:\Users\gabri\OneDrive\Bureau\Python\projects\django website\.django\Lib\site-packages\django\utils\decorators.py", line 48, in _wrapper
    return bound_method(*args, **kwargs)
  File "C:\Users\gabri\OneDrive\Bureau\Python\projects\django website\.django\Lib\site-packages\django\utils\decorators.py", line 185, in _view_wrapper
    result = _pre_process_request(request, *args, **kwargs)
  File "C:\Users\gabri\OneDrive\Bureau\Python\projects\django website\.django\Lib\site-packages\django\utils\decorators.py", line 131, in _pre_process_request
    result = middleware.process_request(request)
  File "C:\Users\gabri\OneDrive\Bureau\Python\projects\django website\.django\Lib\site-packages\django\middleware\cache.py", line 161, in process_request
    cache_key = get_cache_key(request, self.key_prefix, "GET", cache=self.cache)
  File "C:\Users\gabri\OneDrive\Bureau\Python\projects\django website\.django\Lib\site-packages\django\utils\cache.py", line 392, in get_cache_key
    headerlist = cache.get(cache_key)
  File "C:\Users\gabri\OneDrive\Bureau\Python\projects\django website\.django\Lib\site-packages\debug_toolbar\panels\cache.py", line 42, in wrapper
    return panel._record_call(cache, name, original_method, args, kwargs)
           ~~~~~~~~~~~~~~~~~~^^^^^^^^^^^^^^^^^^^^^^^^^^^^^^^^^^^^^^^^^^^^
  File "C:\Users\gabri\OneDrive\Bureau\Python\projects\django website\.django\Lib\site-packages\debug_toolbar\panels\cache.py", line 151, in _record_call
    value = original_method(*args, **kwargs)
  File "C:\Users\gabri\OneDrive\Bureau\Python\projects\django website\.django\Lib\site-packages\django_redis\cache.py", line 92, in get
    value = self._get(key, default, version, client)
  File "C:\Users\gabri\OneDrive\Bureau\Python\projects\django website\.django\Lib\site-packages\django_redis\cache.py", line 36, in _decorator
    raise e.__cause__  # noqa: B904
    ^^^^^^^^^^^^^^^^^
  File "C:\Users\gabri\OneDrive\Bureau\Python\projects\django website\.django\Lib\site-packages\django_redis\client\default.py", line 298, in get
    value = client.get(key)
  File "C:\Users\gabri\OneDrive\Bureau\Python\projects\django website\.django\Lib\site-packages\redis\commands\core.py", line 1829, in get
    return self.execute_command("GET", name, keys=[name])
           ~~~~~~~~~~~~~~~~~~~~^^^^^^^^^^^^^^^^^^^^^^^^^^
  File "C:\Users\gabri\OneDrive\Bureau\Python\projects\django website\.django\Lib\site-packages\redis\client.py", line 621, in execute_command
    return self._execute_command(*args, **options)
           ~~~~~~~~~~~~~~~~~~~~~^^^^^^^^^^^^^^^^^^
  File "C:\Users\gabri\OneDrive\Bureau\Python\projects\django website\.django\Lib\site-packages\redis\client.py", line 627, in _execute_command
    conn = self.connection or pool.get_connection()
                              ~~~~~~~~~~~~~~~~~~~^^
  File "C:\Users\gabri\OneDrive\Bureau\Python\projects\django website\.django\Lib\site-packages\redis\utils.py", line 195, in wrapper
    return func(*args, **kwargs)
  File "C:\Users\gabri\OneDrive\Bureau\Python\projects\django website\.django\Lib\site-packages\redis\connection.py", line 1533, in get_connection
    connection.connect()
    ~~~~~~~~~~~~~~~~~~^^
  File "C:\Users\gabri\OneDrive\Bureau\Python\projects\django website\.django\Lib\site-packages\redis\connection.py", line 380, in connect
    self.connect_check_health(check_health=True)
    ~~~~~~~~~~~~~~~~~~~~~~~~~^^^^^^^^^^^^^^^^^^^
  File "C:\Users\gabri\OneDrive\Bureau\Python\projects\django website\.django\Lib\site-packages\redis\connection.py", line 395, in connect_check_health
    raise TimeoutError("Timeout connecting to server")
redis.exceptions.TimeoutError: Timeout connecting to server
"GET /dashboard/home/ HTTP/1.1" 500 181158
Internal Server Error: /
Traceback (most recent call last):
  File "/usr/local/lib/python3.11/site-packages/django_redis/cache.py", line 29, in _decorator
    return method(self, *args, **kwargs)
           ^^^^^^^^^^^^^^^^^^^^^^^^^^^^^
  File "/usr/local/lib/python3.11/site-packages/django_redis/cache.py", line 81, in set
    return self.client.set(*args, **kwargs)
           ^^^^^^^^^^^^^^^^^^^^^^^^^^^^^^^^
  File "/usr/local/lib/python3.11/site-packages/django_redis/client/default.py", line 224, in set
    raise ConnectionInterrupted(connection=client) from e
django_redis.exceptions.ConnectionInterrupted: Redis ConnectionError: Error -2 connecting to redis:6379. Name or service not known.

During handling of the above exception, another exception occurred:

Traceback (most recent call last):
  File "/usr/local/lib/python3.11/site-packages/django/core/handlers/exception.py", line 55, in inner
    response = get_response(request)
               ^^^^^^^^^^^^^^^^^^^^^
  File "/usr/local/lib/python3.11/site-packages/django/core/handlers/base.py", line 220, in _get_response
    response = response.render()
               ^^^^^^^^^^^^^^^^^
  File "/usr/local/lib/python3.11/site-packages/django/template/response.py", line 114, in render
    self.content = self.rendered_content
                   ^^^^^^^^^^^^^^^^^^^^^
  File "/usr/local/lib/python3.11/site-packages/django/template/response.py", line 92, in rendered_content
    return template.render(context, self._request)
           ^^^^^^^^^^^^^^^^^^^^^^^^^^^^^^^^^^^^^^^
  File "/usr/local/lib/python3.11/site-packages/django/template/backends/django.py", line 107, in render
    return self.template.render(context)
           ^^^^^^^^^^^^^^^^^^^^^^^^^^^^^
  File "/usr/local/lib/python3.11/site-packages/django/template/base.py", line 169, in render
    with context.bind_template(self):
  File "/usr/local/lib/python3.11/contextlib.py", line 137, in __enter__
    return next(self.gen)
           ^^^^^^^^^^^^^^
  File "/usr/local/lib/python3.11/site-packages/debug_toolbar/panels/templates/panel.py", line 51, in _request_context_bind_template
    context = processor(self.request)
              ^^^^^^^^^^^^^^^^^^^^^^^
  File "/app/dashboard/context_processor.py", line 4, in unread_messages_count
    if request.user.is_authenticated:
       ^^^^^^^^^^^^^^^^^^^^^^^^^^^^^
  File "/usr/local/lib/python3.11/site-packages/django/utils/functional.py", line 251, in inner
    self._setup()
  File "/usr/local/lib/python3.11/site-packages/django/utils/functional.py", line 404, in _setup
    self._wrapped = self._setupfunc()
                    ^^^^^^^^^^^^^^^^^
  File "/usr/local/lib/python3.11/site-packages/django/contrib/auth/middleware.py", line 40, in <lambda>
    request.user = SimpleLazyObject(lambda: get_user(request))
                                            ^^^^^^^^^^^^^^^^^
  File "/usr/local/lib/python3.11/site-packages/django/contrib/auth/middleware.py", line 20, in get_user
    request._cached_user = auth.get_user(request)
                           ^^^^^^^^^^^^^^^^^^^^^^
  File "/usr/local/lib/python3.11/site-packages/django/contrib/auth/__init__.py", line 304, in get_user
    user_id = _get_user_session_key(request)
              ^^^^^^^^^^^^^^^^^^^^^^^^^^^^^^
  File "/usr/local/lib/python3.11/site-packages/django/contrib/auth/__init__.py", line 95, in _get_user_session_key
    return get_user_model()._meta.pk.to_python(request.session[SESSION_KEY])
                                               ~~~~~~~~~~~~~~~^^^^^^^^^^^^^
  File "/usr/local/lib/python3.11/site-packages/django/contrib/sessions/backends/base.py", line 55, in __getitem__
    return self._session[key]
           ^^^^^^^^^^^^^
  File "/usr/local/lib/python3.11/site-packages/django/contrib/sessions/backends/base.py", line 249, in _get_session
    self._session_cache = self.load()
                          ^^^^^^^^^^^
  File "/usr/local/lib/python3.11/site-packages/django/contrib/sessions/backends/cached_db.py", line 46, in load
    self._cache.set(
  File "/usr/local/lib/python3.11/site-packages/django_redis/cache.py", line 36, in _decorator
    raise e.__cause__  # noqa: B904
    ^^^^^^^^^^^^^^^^^
  File "/usr/local/lib/python3.11/site-packages/django_redis/client/default.py", line 214, in set
    return bool(client.set(nkey, nvalue, nx=nx, px=timeout, xx=xx))
                ^^^^^^^^^^^^^^^^^^^^^^^^^^^^^^^^^^^^^^^^^^^^^^^^^^
  File "/usr/local/lib/python3.11/site-packages/redis/commands/core.py", line 2305, in set
    return self.execute_command("SET", *pieces, **options)
           ^^^^^^^^^^^^^^^^^^^^^^^^^^^^^^^^^^^^^^^^^^^^^^^
  File "/usr/local/lib/python3.11/site-packages/redis/client.py", line 621, in execute_command
    return self._execute_command(*args, **options)
           ^^^^^^^^^^^^^^^^^^^^^^^^^^^^^^^^^^^^^^^
  File "/usr/local/lib/python3.11/site-packages/redis/client.py", line 627, in _execute_command
    conn = self.connection or pool.get_connection()
                              ^^^^^^^^^^^^^^^^^^^^^
  File "/usr/local/lib/python3.11/site-packages/redis/utils.py", line 195, in wrapper
    return func(*args, **kwargs)
           ^^^^^^^^^^^^^^^^^^^^^
  File "/usr/local/lib/python3.11/site-packages/redis/connection.py", line 1533, in get_connection
    connection.connect()
  File "/usr/local/lib/python3.11/site-packages/redis/connection.py", line 380, in connect
    self.connect_check_health(check_health=True)
  File "/usr/local/lib/python3.11/site-packages/redis/connection.py", line 397, in connect_check_health
    raise ConnectionError(self._error_message(e))
redis.exceptions.ConnectionError: Error -2 connecting to redis:6379. Name or service not known.
Internal Server Error: /
Traceback (most recent call last):
  File "/usr/local/lib/python3.11/site-packages/django_redis/cache.py", line 29, in _decorator
    return method(self, *args, **kwargs)
           ^^^^^^^^^^^^^^^^^^^^^^^^^^^^^
  File "/usr/local/lib/python3.11/site-packages/django_redis/cache.py", line 81, in set
    return self.client.set(*args, **kwargs)
           ^^^^^^^^^^^^^^^^^^^^^^^^^^^^^^^^
  File "/usr/local/lib/python3.11/site-packages/django_redis/client/default.py", line 224, in set
    raise ConnectionInterrupted(connection=client) from e
django_redis.exceptions.ConnectionInterrupted: Redis ConnectionError: Error -2 connecting to redis:6379. Name or service not known.

During handling of the above exception, another exception occurred:

Traceback (most recent call last):
  File "/usr/local/lib/python3.11/site-packages/django/core/handlers/exception.py", line 55, in inner
    response = get_response(request)
               ^^^^^^^^^^^^^^^^^^^^^
  File "/usr/local/lib/python3.11/site-packages/django/core/handlers/base.py", line 220, in _get_response
    response = response.render()
               ^^^^^^^^^^^^^^^^^
  File "/usr/local/lib/python3.11/site-packages/django/template/response.py", line 114, in render
    self.content = self.rendered_content
                   ^^^^^^^^^^^^^^^^^^^^^
  File "/usr/local/lib/python3.11/site-packages/django/template/response.py", line 92, in rendered_content
    return template.render(context, self._request)
           ^^^^^^^^^^^^^^^^^^^^^^^^^^^^^^^^^^^^^^^
  File "/usr/local/lib/python3.11/site-packages/django/template/backends/django.py", line 107, in render
    return self.template.render(context)
           ^^^^^^^^^^^^^^^^^^^^^^^^^^^^^
  File "/usr/local/lib/python3.11/site-packages/django/template/base.py", line 169, in render
    with context.bind_template(self):
  File "/usr/local/lib/python3.11/contextlib.py", line 137, in __enter__
    return next(self.gen)
           ^^^^^^^^^^^^^^
  File "/usr/local/lib/python3.11/site-packages/debug_toolbar/panels/templates/panel.py", line 51, in _request_context_bind_template
    context = processor(self.request)
              ^^^^^^^^^^^^^^^^^^^^^^^
  File "/app/dashboard/context_processor.py", line 4, in unread_messages_count
    if request.user.is_authenticated:
       ^^^^^^^^^^^^^^^^^^^^^^^^^^^^^
  File "/usr/local/lib/python3.11/site-packages/django/utils/functional.py", line 251, in inner
    self._setup()
  File "/usr/local/lib/python3.11/site-packages/django/utils/functional.py", line 404, in _setup
    self._wrapped = self._setupfunc()
                    ^^^^^^^^^^^^^^^^^
  File "/usr/local/lib/python3.11/site-packages/django/contrib/auth/middleware.py", line 40, in <lambda>
    request.user = SimpleLazyObject(lambda: get_user(request))
                                            ^^^^^^^^^^^^^^^^^
  File "/usr/local/lib/python3.11/site-packages/django/contrib/auth/middleware.py", line 20, in get_user
    request._cached_user = auth.get_user(request)
                           ^^^^^^^^^^^^^^^^^^^^^^
  File "/usr/local/lib/python3.11/site-packages/django/contrib/auth/__init__.py", line 304, in get_user
    user_id = _get_user_session_key(request)
              ^^^^^^^^^^^^^^^^^^^^^^^^^^^^^^
  File "/usr/local/lib/python3.11/site-packages/django/contrib/auth/__init__.py", line 95, in _get_user_session_key
    return get_user_model()._meta.pk.to_python(request.session[SESSION_KEY])
                                               ~~~~~~~~~~~~~~~^^^^^^^^^^^^^
  File "/usr/local/lib/python3.11/site-packages/django/contrib/sessions/backends/base.py", line 55, in __getitem__
    return self._session[key]
           ^^^^^^^^^^^^^
  File "/usr/local/lib/python3.11/site-packages/django/contrib/sessions/backends/base.py", line 249, in _get_session
    self._session_cache = self.load()
                          ^^^^^^^^^^^
  File "/usr/local/lib/python3.11/site-packages/django/contrib/sessions/backends/cached_db.py", line 46, in load
    self._cache.set(
  File "/usr/local/lib/python3.11/site-packages/django_redis/cache.py", line 36, in _decorator
    raise e.__cause__  # noqa: B904
    ^^^^^^^^^^^^^^^^^
  File "/usr/local/lib/python3.11/site-packages/django_redis/client/default.py", line 214, in set
    return bool(client.set(nkey, nvalue, nx=nx, px=timeout, xx=xx))
                ^^^^^^^^^^^^^^^^^^^^^^^^^^^^^^^^^^^^^^^^^^^^^^^^^^
  File "/usr/local/lib/python3.11/site-packages/redis/commands/core.py", line 2305, in set
    return self.execute_command("SET", *pieces, **options)
           ^^^^^^^^^^^^^^^^^^^^^^^^^^^^^^^^^^^^^^^^^^^^^^^
  File "/usr/local/lib/python3.11/site-packages/redis/client.py", line 621, in execute_command
    return self._execute_command(*args, **options)
           ^^^^^^^^^^^^^^^^^^^^^^^^^^^^^^^^^^^^^^^
  File "/usr/local/lib/python3.11/site-packages/redis/client.py", line 627, in _execute_command
    conn = self.connection or pool.get_connection()
                              ^^^^^^^^^^^^^^^^^^^^^
  File "/usr/local/lib/python3.11/site-packages/redis/utils.py", line 195, in wrapper
    return func(*args, **kwargs)
           ^^^^^^^^^^^^^^^^^^^^^
  File "/usr/local/lib/python3.11/site-packages/redis/connection.py", line 1533, in get_connection
    connection.connect()
  File "/usr/local/lib/python3.11/site-packages/redis/connection.py", line 380, in connect
    self.connect_check_health(check_health=True)
  File "/usr/local/lib/python3.11/site-packages/redis/connection.py", line 397, in connect_check_health
    raise ConnectionError(self._error_message(e))
redis.exceptions.ConnectionError: Error -2 connecting to redis:6379. Name or service not known.
Internal Server Error: /
Traceback (most recent call last):
  File "/usr/local/lib/python3.11/site-packages/django_redis/cache.py", line 29, in _decorator
    return method(self, *args, **kwargs)
           ^^^^^^^^^^^^^^^^^^^^^^^^^^^^^
  File "/usr/local/lib/python3.11/site-packages/django_redis/cache.py", line 81, in set
    return self.client.set(*args, **kwargs)
           ^^^^^^^^^^^^^^^^^^^^^^^^^^^^^^^^
  File "/usr/local/lib/python3.11/site-packages/django_redis/client/default.py", line 224, in set
    raise ConnectionInterrupted(connection=client) from e
django_redis.exceptions.ConnectionInterrupted: Redis ConnectionError: Error -2 connecting to redis:6379. Name or service not known.

During handling of the above exception, another exception occurred:

Traceback (most recent call last):
  File "/usr/local/lib/python3.11/site-packages/django/core/handlers/exception.py", line 55, in inner
    response = get_response(request)
               ^^^^^^^^^^^^^^^^^^^^^
  File "/usr/local/lib/python3.11/site-packages/django/core/handlers/base.py", line 220, in _get_response
    response = response.render()
               ^^^^^^^^^^^^^^^^^
  File "/usr/local/lib/python3.11/site-packages/django/template/response.py", line 114, in render
    self.content = self.rendered_content
                   ^^^^^^^^^^^^^^^^^^^^^
  File "/usr/local/lib/python3.11/site-packages/django/template/response.py", line 92, in rendered_content
    return template.render(context, self._request)
           ^^^^^^^^^^^^^^^^^^^^^^^^^^^^^^^^^^^^^^^
  File "/usr/local/lib/python3.11/site-packages/django/template/backends/django.py", line 107, in render
    return self.template.render(context)
           ^^^^^^^^^^^^^^^^^^^^^^^^^^^^^
  File "/usr/local/lib/python3.11/site-packages/django/template/base.py", line 169, in render
    with context.bind_template(self):
  File "/usr/local/lib/python3.11/contextlib.py", line 137, in __enter__
    return next(self.gen)
           ^^^^^^^^^^^^^^
  File "/usr/local/lib/python3.11/site-packages/debug_toolbar/panels/templates/panel.py", line 51, in _request_context_bind_template
    context = processor(self.request)
              ^^^^^^^^^^^^^^^^^^^^^^^
  File "/app/dashboard/context_processor.py", line 4, in unread_messages_count
    if request.user.is_authenticated:
       ^^^^^^^^^^^^^^^^^^^^^^^^^^^^^
  File "/usr/local/lib/python3.11/site-packages/django/utils/functional.py", line 251, in inner
    self._setup()
  File "/usr/local/lib/python3.11/site-packages/django/utils/functional.py", line 404, in _setup
    self._wrapped = self._setupfunc()
                    ^^^^^^^^^^^^^^^^^
  File "/usr/local/lib/python3.11/site-packages/django/contrib/auth/middleware.py", line 40, in <lambda>
    request.user = SimpleLazyObject(lambda: get_user(request))
                                            ^^^^^^^^^^^^^^^^^
  File "/usr/local/lib/python3.11/site-packages/django/contrib/auth/middleware.py", line 20, in get_user
    request._cached_user = auth.get_user(request)
                           ^^^^^^^^^^^^^^^^^^^^^^
  File "/usr/local/lib/python3.11/site-packages/django/contrib/auth/__init__.py", line 304, in get_user
    user_id = _get_user_session_key(request)
              ^^^^^^^^^^^^^^^^^^^^^^^^^^^^^^
  File "/usr/local/lib/python3.11/site-packages/django/contrib/auth/__init__.py", line 95, in _get_user_session_key
    return get_user_model()._meta.pk.to_python(request.session[SESSION_KEY])
                                               ~~~~~~~~~~~~~~~^^^^^^^^^^^^^
  File "/usr/local/lib/python3.11/site-packages/django/contrib/sessions/backends/base.py", line 55, in __getitem__
    return self._session[key]
           ^^^^^^^^^^^^^
  File "/usr/local/lib/python3.11/site-packages/django/contrib/sessions/backends/base.py", line 249, in _get_session
    self._session_cache = self.load()
                          ^^^^^^^^^^^
  File "/usr/local/lib/python3.11/site-packages/django/contrib/sessions/backends/cached_db.py", line 46, in load
    self._cache.set(
  File "/usr/local/lib/python3.11/site-packages/django_redis/cache.py", line 36, in _decorator
    raise e.__cause__  # noqa: B904
    ^^^^^^^^^^^^^^^^^
  File "/usr/local/lib/python3.11/site-packages/django_redis/client/default.py", line 214, in set
    return bool(client.set(nkey, nvalue, nx=nx, px=timeout, xx=xx))
                ^^^^^^^^^^^^^^^^^^^^^^^^^^^^^^^^^^^^^^^^^^^^^^^^^^
  File "/usr/local/lib/python3.11/site-packages/redis/commands/core.py", line 2305, in set
    return self.execute_command("SET", *pieces, **options)
           ^^^^^^^^^^^^^^^^^^^^^^^^^^^^^^^^^^^^^^^^^^^^^^^
  File "/usr/local/lib/python3.11/site-packages/redis/client.py", line 621, in execute_command
    return self._execute_command(*args, **options)
           ^^^^^^^^^^^^^^^^^^^^^^^^^^^^^^^^^^^^^^^
  File "/usr/local/lib/python3.11/site-packages/redis/client.py", line 627, in _execute_command
    conn = self.connection or pool.get_connection()
                              ^^^^^^^^^^^^^^^^^^^^^
  File "/usr/local/lib/python3.11/site-packages/redis/utils.py", line 195, in wrapper
    return func(*args, **kwargs)
           ^^^^^^^^^^^^^^^^^^^^^
  File "/usr/local/lib/python3.11/site-packages/redis/connection.py", line 1533, in get_connection
    connection.connect()
  File "/usr/local/lib/python3.11/site-packages/redis/connection.py", line 380, in connect
    self.connect_check_health(check_health=True)
  File "/usr/local/lib/python3.11/site-packages/redis/connection.py", line 397, in connect_check_health
    raise ConnectionError(self._error_message(e))
redis.exceptions.ConnectionError: Error -2 connecting to redis:6379. Name or service not known.
